File: example_data/M20171121_Pd_one_torlon_M(T)_at_10000_Oe_background.dat
[Header]
; MPMS3 Data File (default extension .dat)
; Copyright (c) 2007, Quantum Design, Inc. All rights reserved.
TITLE,Pd with one Torlon [Background Data]
FILEOPENTIME,3720439357.30168,11/21/2017,3:23 pm
BYAPP,SQUID AC,0.9.1.0
INFO,MPMS3 Measurement Release 1.1.16 Build 347, MultiVu Release 2.3.3.2,APPNAME
INFO,0,MOMENT_UNITS
INFO,Torlon,SAMPLE_MATERIAL
INFO,Background data: One Torlon offcentered, used in Pd with one Torlon,SAMPLE_COMMENT
INFO,,SAMPLE_MASS
INFO,,SAMPLE_VOLUME
INFO,,SAMPLE_MOLECULAR_WEIGHT
INFO,,SAMPLE_SIZE
INFO,,SAMPLE_SHAPE
INFO,Straw,SAMPLE_HOLDER
INFO,Standard,SAMPLE_HOLDER_DETAIL
INFO,57.92,SAMPLE_OFFSET
DATATYPE,COMMENT,1
DATATYPE,TIME,2
STARTUPAXIS,X,2
STARTUPAXIS,Y1,5
FIELDGROUP, VSM,2,3,4,5,6,8,9,10,11,14,15
FIELDGROUP, DC, 2,3,4,14,56,57,58,59,60,61,62,63,64,65,66,67,68,69
FIELDGROUP, AC, 2,3,4,11,16,17,18,19,20,21,22,23,24,25,26,27,28,29,30
STARTUPGROUP, All
[Data]
Comment,Time Stamp (sec),Temperature (K),Magnetic Field (Oe),Moment (emu),M. Std. Err. (emu),Transport Action,Averaging Time (sec),Frequency (Hz),Peak Amplitude (mm),Center Position (mm),Lockin Signal' (V),Lockin Signal (V),Range,M. Quad. Signal (emu),AC Moment (emu),AC M. Std Err. (emu),AC Phase (deg),AC Phase Std. Err. (deg),AC Susceptibility (emu/Oe),AC Suscept. Std Err. (emu/Oe),AC X' (emu/Oe),AC X' Std Err. (emu/Oe),AC X'' (emu/Oe),AC X'' Std Err. (emu/Oe),AC Drive (Oe),AC Frequency (Hz),AC Averaging Time (sec),AC Cycles,AC Range,AC Measure Type,AC Signal' (V),AC Signal'' (V),AC Trim Coil Ratio,AC Trim Coil Phase,Min. Temperature (K),Max. Temperature (K),Min. Field (Oe),Max. Field (Oe),Mass (grams),Motor Lag (deg),Pressure (Torr),Measure Count,Measurement Number,SQUID Status (code),Motor Status (code),Measure Status (code),Motor Current (amps),Motor Temp. (C),Temp. Status (code),Field Status (code),Chamber Status (code),Chamber Temp (K),Redirection State,Average Temp (K),Rotation Angle (deg),Rotator state,DC Moment Fixed Ctr (emu),DC Moment Err Fixed Ctr (emu),DC Moment Free Ctr (emu),DC Moment Err Free Ctr (emu),DC Fixed Fit,DC Free Fit,DC Calculated Center (mm),DC Calculated Center Err (mm),DC Scan Length (mm),DC Scan Time (s),DC Number of Points,DC Squid Drift,DC Min V (V),DC Max V (V),DC Scans per Measure,Map 01,Map 02,Map 03,Map 04,Map 05,Map 06,Map 07,Map 08,Map 09,Map 10,Map 11,Map 12,Map 13,Map 14,Map 15,Map 16
,3720439433.23417,299.996398925781,10000.1865234375,,,6,,,,39.6060001694262,,,1,,,,,,,,,,,,,,,,,,,,,,299.989044189453,300.003753662109,10000.1865234375,10000.1865234375,,,6.74624919891357,-99999999,1,0,0,0,0.013885498046875,31.2805480957031,1,1,1,299.993347167969,0,299.996813964844,,,-0.000224023577628388,1.39357324633592E-5,-0.000281710435458073,1.40689649707278E-5,0.402369767427444,0.9486945271492,37.227165222168,0.235830515623093,30,4,200,0.118269607424736,-0.517214834690094,1.39055478572845,1,,,,,,,,,,,,,,,,
,3720439712.84036,291.661254882812,10000.1865234375,,,6,,,,39.5698524227932,,,1,,,,,,,,,,,,,,,,,,,,,,291.635040283203,291.717102050781,10000.1865234375,10000.1865234375,,,6.67479228973389,-99999999,1,0,0,0,0.0139617919921875,30.7917900085449,1,1,1,291.631652832031,0,291.685245090061,,,-0.000225992567835433,1.39445411528659E-5,-0.000282053202553524,1.40736663119371E-5,0.411240190267563,0.970484972000122,37.2236366271973,0.233912214636803,30,4,200,2.15669342651381E-6,0.113034605979919,1.49143636226654,1,,,,,,,,,,,,,,,,
,3720439957.7418,283.692230224609,10000.1865234375,,,6,,,,39.539180802758,,,1,,,,,,,,,,,,,,,,,,,,,,283.664123535156,283.752471923828,10000.1865234375,10000.1865234375,,,6.61474180221558,-99999999,1,0,0,0,0.013885498046875,30.7917900085449,1,1,1,283.663299560547,0,283.717210557726,,,-0.000223503783800938,1.39233481081594E-5,-0.00028174323059681,1.40582437772646E-5,0.400831639766693,0.970373272895813,37.1451377868652,0.236169755458832,30,4,200,-0.000473405467346311,0.0991695150732994,1.47818100452423,1,,,,,,,,,,,,,,,,
,3720440192.54732,275.804885864258,10000.1865234375,,,6,,,,39.5085813499312,,,1,,,,,,,,,,,,,,,,,,,,,,275.784912109375,275.858551025391,10000.1865234375,10000.1865234375,,,6.56827592849731,-99999999,1,0,0,0,0.013885498046875,31.2805480957031,1,1,1,275.786651611328,0,275.828362358941,,,-0.000220819714962727,1.3908855921827E-5,-0.000281563157749521,1.40491750578707E-5,0.389261692762375,0.970573961734772,37.0606880187988,0.238801419734955,30,4,200,-0.000694711168762296,0.0599145404994488,1.43912971019745,1,,,,,,,,,,,,,,,,
,3720440424.53209,267.846389770508,10000.1865234375,,,6,,,,39.4825054855205,,,1,,,,,,,,,,,,,,,,,,,,,,267.830474853516,267.901489257813,10000.1865234375,10000.1865234375,,,6.52776527404785,-99999999,1,0,0,0,0.013885498046875,30.7917900085449,1,1,1,267.831909179687,0,267.870676676432,,,-0.000218218877237387,1.38875107003592E-5,-0.000281260912979683,1.40341939825114E-5,0.378872156143188,0.970346868038178,36.9863166809082,0.24128569662571,30,4,200,-0.000808332173619419,0.0155782541260123,1.39259934425354,1,,,,,,,,,,,,,,,,
,3720440666.73113,259.869873046875,10000.1865234375,,,6,,,,39.4517224089337,,,1,,,,,,,,,,,,,,,,,,,,,,259.842529296875,259.926818847656,10000.1865234375,10000.1865234375,,,6.49141407012939,-99999999,1,0,0,0,0.013885498046875,30.7917900085449,1,1,1,259.844268798828,0,259.891523573134,,,-0.00021636333356043,1.38651335214507E-5,-0.000280887674308365,1.40156807239608E-5,0.372106403112412,0.970074653625488,36.9237785339355,0.242966800928116,30,4,200,-0.000430620915722102,-0.0232218448072672,1.35312116146088,1,,,,,,,,,,,,,,,,
,3720440900.16235,251.875190734863,10000.1865234375,,,6,,,,39.416262273719,,,1,,,,,,,,,,,,,,,,,,,,,,251.8505859375,251.924285888672,10000.1865234375,10000.1865234375,,,6.45713138580322,-99999999,1,0,0,0,0,30.7917900085449,1,1,1,251.859619140625,0,251.890526665582,,,-0.000214873524217413,1.38556491698997E-5,-0.000280754362299113,1.40092504857897E-5,0.36616587638855,0.969545364379883,36.8600654602051,0.244501635432243,30,4,200,0.000215499618207105,-0.0583957061171532,1.31711828708649,1,,,,,,,,,,,,,,,,
,3720441138.90919,243.86466217041,10000.1865234375,,,6,,,,39.3799481371599,,,1,,,,,,,,,,,,,,,,,,,,,,243.839782714844,243.91716003418,10000.1865234375,10000.1865234375,,,6.42467641830444,-99999999,1,0,0,0,0.013885498046875,31.2805480957031,1,1,1,243.842559814453,0,243.885109795464,,,-0.000213654464952972,1.38329840356729E-5,-0.000280335345665631,1.39883433382067E-5,0.362367689609528,0.969538331031799,36.8058586120605,0.245498672127724,30,4,200,-0.000586914422456175,-0.088548831641674,1.28467965126038,1,,,,,,,,,,,,,,,,
,3720441376.5533,235.869529724121,10000.1865234375,,,6,,,,39.3388460380791,,,1,,,,,,,,,,,,,,,,,,,,,,235.850204467773,235.914657592773,10000.1865234375,10000.1865234375,,,6.39219236373901,-99999999,1,0,0,0,0,31.2805480957031,1,1,1,235.856063842773,0,235.883741760254,,,-0.000212862059206435,1.38163543789884E-5,-0.000280017680489729,1.39726415664435E-5,0.360039532184601,0.969200909137726,36.7537422180176,0.246116921305656,30,4,200,-0.000444586097728461,-0.116714142262936,1.25548553466797,1,,,,,,,,,,,,,,,,
,3720441613.44771,227.872062683105,10000.1865234375,,,6,,,,39.3034725536068,,,1,,,,,,,,,,,,,,,,,,,,,,227.848129272461,227.917526245117,10000.1865234375,10000.1865234375,,,6.35969257354736,-99999999,1,0,0,0,0.013885498046875,30.7917900085449,1,1,1,227.852874755859,0,227.886964586046,,,-0.0002121405595168,1.38137419242936E-5,-0.000280012319127163,1.39718681479344E-5,0.357097655534744,0.970400512218475,36.7033004760742,0.246912926435471,30,4,200,-0.00032978318631649,-0.142007067799568,1.23010182380676,1,,,,,,,,,,,,,,,,
,3720441848.41193,219.874122619629,10000.1865234375,,,6,,,,39.2622816621606,,,1,,,,,,,,,,,,,,,,,,,,,,219.85530090332,219.913833618164,10000.1865234375,10000.1865234375,,,6.3273024559021,-99999999,1,0,0,0,0,30.7917900085449,1,1,1,219.858215332031,0,219.888702392578,,,-0.000211392290758494,1.37988465978625E-5,-0.0002797381216718,1.39583595291476E-5,0.35486713051796,0.96998530626297,36.6518974304199,0.247525632381439,30,4,200,-0.00041604321449995,-0.165923684835434,1.20649921894073,1,,,,,,,,,,,,,,,,
,3720442080.12936,211.873138427734,10000.1865234375,,,6,,,,39.2265003071057,,,1,,,,,,,,,,,,,,,,,,,,,,211.848861694336,211.913726806641,10000.1865234375,10000.1865234375,,,6.2967414855957,-99999999,1,0,0,0,0,30.7917900085449,1,1,1,211.853256225586,0,211.884848700629,,,-0.000210619420864787,1.378963916974E-5,-0.000279588402299864,1.39507059436055E-5,0.352170258760452,0.97042328119278,36.6026725769043,0.248257994651794,30,4,200,-0.000799793167971075,-0.182652816176414,1.18700230121613,1,,,,,,,,,,,,,,,,
,3720442320.38214,203.874755859375,10000.1865234375,,,6,,,,39.1856456143807,,,1,,,,,,,,,,,,,,,,,,,,,,203.846145629883,203.913803100586,10000.1865234375,10000.1865234375,,,6.26289987564087,-99999999,1,0,0,0,0.013885498046875,30.7917900085449,1,1,1,203.856033325195,0,203.885230170356,,,-0.000210241423597276,1.37800456014621E-5,-0.000279403064522594,1.39412761720736E-5,0.351186126470566,0.970857322216034,36.5565223693848,0.248541221022606,30,4,200,-0.00066732446430251,-0.196075990796089,1.17437875270844,1,,,,,,,,,,,,,,,,
,3720442544.36545,195.881881713867,10000.1865234375,,,6,,,,39.1498263898778,,,1,,,,,,,,,,,,,,,,,,,,,,195.857803344727,195.923904418945,10000.1865234375,10000.1865234375,,,6.22987222671509,-99999999,1,0,0,0,0.013885498046875,30.7917900085449,1,1,1,195.86328125,0,195.89582824707,,,-0.000209587439471651,1.37647812799123E-5,-0.000279117749153779,1.3927191860397E-5,0.349400967359543,0.970489025115967,36.5124816894531,0.249039843678474,30,4,200,-0.000705702346749604,-0.207138329744339,1.16157388687134,1,,,,,,,,,,,,,,,,
,3720442766.55484,187.886604309082,10000.1865234375,,,6,,,,39.1136010593608,,,1,,,,,,,,,,,,,,,,,,,,,,187.86311340332,187.92546081543,10000.1865234375,10000.1865234375,,,6.19666242599487,-99999999,1,0,0,0,0.013885498046875,30.3030319213867,1,1,1,187.876907348633,0,187.896665785048,,,-0.000208955538504961,1.37524319428432E-5,-0.000278907550554449,1.39164991395443E-5,0.347526758909225,0.970994174480438,36.4666061401367,0.249584749341011,30,4,200,-0.000495209649670869,-0.221583783626556,1.14768779277802,1,,,,,,,,,,,,,,,,
,3720442983.45817,179.891136169434,10000.1865234375,,,6,,,,39.0782848735385,,,1,,,,,,,,,,,,,,,,,,,,,,179.866577148438,179.921966552734,10000.1865234375,10000.1865234375,,,6.16668224334717,-99999999,1,0,0,0,0.0138092041015625,30.7917900085449,1,1,1,179.880966186523,0,179.894667053223,,,-0.000208088299087058,1.37242129241082E-5,-0.000278335368523085,1.3887992960238E-5,0.345680862665176,0.970897793769836,36.4224395751953,0.250096678733826,30,4,200,-0.000680535158608109,-0.230477914214134,1.13545143604279,1,,,,,,,,,,,,,,,,
,3720443198.08543,171.894493103027,10000.1865234375,,,6,,,,39.0475540818245,,,1,,,,,,,,,,,,,,,,,,,,,,171.861358642578,171.922378540039,10000.1865234375,10000.1865234375,,,6.13651895523071,-99999999,1,0,0,0,0,30.7917900085449,1,1,1,171.891128540039,0,171.893102010091,,,-0.000207296736782687,1.37088022010233E-5,-0.000278045687391751,1.38736273363766E-5,0.343342185020447,0.970674514770508,36.3804359436035,0.250773996114731,30,4,200,-0.000204655691049993,-0.239506617188454,1.12527275085449,1,,,,,,,,,,,,,,,,
,3720443416.41959,163.888877868652,10000.1865234375,,,6,,,,39.0118977885863,,,1,,,,,,,,,,,,,,,,,,,,,,163.863540649414,163.919784545898,10000.1865234375,10000.1865234375,,,6.1056170463562,-99999999,1,0,0,0,0.013885498046875,30.7917900085449,1,1,1,163.880874633789,0,163.89394124349,,,-0.000206763992530952,1.36938247238452E-5,-0.000277779382489445,1.38604424530333E-5,0.342062950134277,0.970411002635956,36.3388481140137,0.251151204109192,30,4,200,-0.00045178976142779,-0.244157269597054,1.11909866333008,1,,,,,,,,,,,,,,,,
,3720443625.40161,155.896667480469,10000.1865234375,,,6,,,,38.981561623568,,,1,,,,,,,,,,,,,,,,,,,,,,155.874847412109,155.924072265625,10000.1865234375,10000.1865234375,,,6.07476806640625,-99999999,1,0,0,0,0.013885498046875,30.7917900085449,1,1,1,155.89372253418,0,155.900156656901,,,-0.00020584213440886,1.36676669989209E-5,-0.00027728743006997,1.38358832935874E-5,0.339868694543839,0.970442473888397,36.2976226806641,0.251804828643799,30,4,200,-0.000519556633662432,-0.24569196999073,1.1140011548996,1,,,,,,,,,,,,,,,,
,3720443818.71833,147.880760192871,10000.1865234375,,,6,,,,38.9510216217691,,,1,,,,,,,,,,,,,,,,,,,,,,147.859130859375,147.912124633789,10000.1865234375,10000.1865234375,,,6.04258584976196,-99999999,1,0,0,0,0.0139617919921875,30.7917900085449,1,1,1,147.875900268555,0,147.886706882053,,,-0.00020503070961947,1.36446760723353E-5,-0.000276833190132646,1.3813367595881E-5,0.337938845157623,0.970074892044067,36.2579879760742,0.252371519804001,30,4,200,-0.000270397576969117,-0.246247634291649,1.11154842376709,1,,,,,,,,,,,,,,,,
,3720444011.45363,139.891502380371,10000.1865234375,,,6,,,,38.9256942863532,,,1,,,,,,,,,,,,,,,,,,,,,,139.862716674805,139.904769897461,10000.1865234375,10000.1865234375,,,6.00796508789063,-99999999,1,0,0,0,0,30.7917900085449,1,1,1,139.900604248047,0,139.88576965332,,,-0.000203812121993031,1.36133815551202E-5,-0.000276220929078109,1.37832669825589E-5,0.33484822511673,0.969007968902588,36.2182121276855,0.253295451402664,30,4,200,0.000572852324694395,-0.245142996311188,1.10960209369659,1,,,,,,,,,,,,,,,,
,3720444159.33662,131.683609008789,10000.1865234375,,,6,,,,38.9001003565308,,,1,,,,,,,,,,,,,,,,,,,,,,131.652435302734,131.700225830078,10000.1865234375,10000.1865234375,,,5.97221803665161,-99999999,1,0,0,0,0,30.7917900085449,1,1,1,131.714782714844,0,131.676829528809,,,-0.000203487467607662,1.359982823941E-5,-0.00027595574837383,1.37697366566777E-5,0.334347128868103,0.969704687595367,36.1895790100098,0.253446400165558,30,4,200,-0.00052830867934972,-0.241245627403259,1.11208665370941,1,,,,,,,,,,,,,,,,
,3720444304.95036,123.891647338867,10000.1865234375,,,6,,,,38.8747997389881,,,1,,,,,,,,,,,,,,,,,,,,,,123.866088867188,123.899612426758,10000.1865234375,10000.1865234375,,,5.94330883026123,-99999999,1,0,0,0,0.013885498046875,30.7917900085449,1,1,1,123.903755187988,0,123.883562469482,,,-0.000201612681814659,1.35457603577114E-5,-0.000274888685595066,1.37170643382894E-5,0.329973876476288,0.968370258808136,36.1438331604004,0.254816651344299,30,4,200,0.00125392677728087,-0.242549687623978,1.10628640651703,1,,,,,,,,,,,,,,,,
,3720444450.04458,115.787906646729,10000.1865234375,,,6,,,,38.8495080872687,,,1,,,,,,,,,,,,,,,,,,,,,,115.761688232422,115.80842590332,10000.1865234375,10000.1865234375,,,5.91130924224854,-99999999,1,0,0,0,0.013885498046875,30.7917900085449,1,1,1,115.814125061035,0,115.783459472656,,,-0.000200839468848237,1.3519445605207E-5,-0.000274377271829726,1.36915515920422E-5,0.328417658805847,0.968353807926178,36.1109161376953,0.255293726921082,30,4,200,0.000561667664442211,-0.237995162606239,1.10856628417969,1,,,,,,,,,,,,,,,,
,3720444592.97284,107.786567687988,10000.1865234375,,,6,,,,38.829246735985,,,1,,,,,,,,,,,,,,,,,,,,,,107.767601013184,107.800415039062,10000.1865234375,10000.1865234375,,,5.88028192520142,-99999999,1,0,0,0,0.0147247314453125,30.7917900085449,1,1,1,107.805534362793,0,107.786348978678,,,-0.000199651342306235,1.34865145965748E-5,-0.000273734501745952,1.36597303277298E-5,0.325576961040497,0.967771172523498,36.0767593383789,0.256170153617859,30,4,200,5.20644207426812E-5,-0.231386348605156,1.11292159557343,1,,,,,,,,,,,,,,,,
,3720444736.50082,99.8250503540039,10000.1865234375,,,6,,,,38.8089724540052,,,1,,,,,,,,,,,,,,,,,,,,,,99.8058700561523,99.8362884521484,10000.1865234375,10000.1865234375,,,5.84994506835938,-99999999,1,0,0,0,0.013885498046875,31.2805480957031,1,1,1,99.8442306518555,0,99.8186805031516,,,-0.000197780517504724,1.34332514178694E-5,-0.000272705642231692,1.36082514693921E-5,0.32120355963707,0.968079149723053,36.0343475341797,0.257584422826767,30,4,200,0.00139199499972165,-0.222357764840126,1.11505925655365,1,,,,,,,,,,,,,,,,
,3720445404.69104,99.9998092651367,10000.1982421875,,,6,,,,38.8011085620566,,,1,,,,,,,,,,,,,,,,,,,,,,99.9950866699219,100.001815795898,10000.1982421875,10000.1982421875,,,5.8418345451355,-99999999,1,0,0,0,0.013885498046875,31.2805480957031,1,1,1,99.9996185302734,0,99.9986839294434,,,-0.000198158520903332,1.34571025713956E-5,-0.000273197333786452,1.36333692591245E-5,0.321311414241791,0.966778635978699,36.0275077819824,0.257559299468994,30,4,200,6.89527005306445E-5,-0.643356859683991,0.692021191120148,1,,,,,,,,,,,,,,,,
,3720445536.89975,92.6749610900879,10000.1982421875,,,6,,,,38.7806456110774,,,1,,,,,,,,,,,,,,,,,,,,,,92.6559219360352,92.6844787597656,10000.1982421875,10000.1982421875,,,5.79686260223389,-99999999,1,0,0,0,0.013885498046875,30.7917900085449,1,1,1,92.6919555664062,0,92.6696304321289,,,-0.000198281349075962,1.34293080223484E-5,-0.000272627810414636,1.3604306129226E-5,0.323456257581711,0.968233168125153,36.0168037414551,0.256857216358185,30,4,200,-0.00141614291351289,-0.620348393917084,0.718323707580566,1,,,,,,,,,,,,,,,,
,3720445660.8986,85.5905914306641,10000.1982421875,,,6,,,,38.7653757033111,,,1,,,,,,,,,,,,,,,,,,,,,,85.5697860717773,85.5967864990234,10000.1982421875,10000.1982421875,,,5.75965404510498,-99999999,1,0,0,0,0.013885498046875,30.7917900085449,1,1,1,85.6041717529297,0,85.5825614929199,,,-0.000196737933815446,1.33743743915599E-5,-0.000271525544812404,1.35500533986588E-5,0.320495843887329,0.966543853282929,35.9878311157227,0.257812321186066,30,4,200,-0.00111195235513151,-0.616885662078857,0.718107342720032,1,,,,,,,,,,,,,,,,
,3720445785.65197,78.4511604309082,10000.1982421875,,,6,,,,38.7502479230807,,,1,,,,,,,,,,,,,,,,,,,,,,78.4371719360352,78.4589614868164,10000.1982421875,10000.1982421875,,,5.72623300552368,-99999999,1,0,0,0,0.013885498046875,30.7917900085449,1,1,1,78.4651489257812,0,78.4472484588623,,,-0.000195055272471291,1.33139026004227E-5,-0.000270329668854341,1.34906583647052E-5,0.317301571369171,0.96591055393219,35.9571876525879,0.258875519037247,30,4,200,-0.000790625170338899,-0.604857921600342,0.722305476665497,1,,,,,,,,,,,,,,,,
,3720445906.0165,71.3508338928223,10000.1982421875,,,6,,,,38.7350852059619,,,1,,,,,,,,,,,,,,,,,,,,,,71.3313217163086,71.3652191162109,10000.1982421875,10000.1982421875,,,5.68840599060059,-99999999,1,0,0,0,0.013885498046875,30.7917900085449,1,1,1,71.3682403564453,0,71.3447273254394,,,-0.000193235222341895,1.32511603809188E-5,-0.000269098626889399,1.34289450692953E-5,0.313690602779388,0.9665287733078,35.9232940673828,0.26008728146553,30,4,200,-0.000466108525870368,-0.586701333522797,0.731165885925293,1,,,,,,,,,,,,,,,,
,3720446026.32143,64.2251815795898,10000.1982421875,,,6,,,,38.7249722158127,,,1,,,,,,,,,,,,,,,,,,,,,,64.2150344848633,64.2304534912109,10000.1982421875,10000.1982421875,,,5.64463567733765,-99999999,1,0,0,0,0.013885498046875,30.7917900085449,1,1,1,64.2353286743164,0,64.2217771742079,,,-0.000191432128068804,1.31999266449986E-5,-0.00026813243308572,1.33805216097517E-5,0.309486478567123,0.966983914375305,35.8915672302246,0.261519938707352,30,4,200,0.000400018237996846,-0.567794024944305,0.743492960929871,1,,,,,,,,,,,,,,,,
,3720446149.01946,57.1115894317627,10000.1982421875,,,6,,,,38.7148502178387,,,1,,,,,,,,,,,,,,,,,,,,,,57.0974273681641,57.1238861083984,10000.1982421875,10000.1982421875,,,5.58512878417969,-99999999,1,0,0,0,0.013885498046875,30.7917900085449,1,1,1,57.0994110107422,0,57.1090032789442,,,-0.000189508054758176,1.30993863955036E-5,-0.000266078611975901,1.3278913935801E-5,0.307632982730865,0.965038180351257,35.8728828430176,0.262166231870651,30,4,200,0.000921675353311002,-0.539474070072174,0.771321535110474,1,,,,,,,,,,,,,,,,
,3720446282.10008,49.9376087188721,10000.1982421875,,,6,,,,38.6996856899899,,,1,,,,,,,,,,,,,,,,,,,,,,49.9250221252441,49.9490852355957,10000.1982421875,10000.1982421875,,,5.51000833511353,-99999999,1,0,0,0,0.0147247314453125,30.7917900085449,1,1,1,49.9262008666992,0,49.9348992241753,,,-0.000187040082543024,1.29717857993896E-5,-0.000263539576232771,1.31523021697951E-5,0.305149435997009,0.96482390165329,35.8455924987793,0.26303419470787,30,4,200,7.80974369263276E-5,-1.65599882602692,0.794010639190674,1,,,,,,,,,,,,,,,,