File: example_data/M20171121_Pd_one_torlon_M(T)_at_10000_Oe.rw.dat
[Header]
; DC Raw Data File (default extension .raw)
; Copyright 2012, Quantum Design, Inc. All rights reserved.
TITLE,Pd with one Torlon
FILEOPENTIME,3720425250.81348,11/21/2017,11:28 am
BYAPP,SQUID AC,0.9.1.0
INFO,MPMS3 Option Release 1.1.16 Build 347, Release 2.3.3.2,APPNAME
INFO,TCI195,COIL_SERIAL_NUMBER
INFO,0,MOMENT_UNITS
INFO,Pd,SAMPLE_MATERIAL
INFO,Using only *one* torlon,SAMPLE_COMMENT
INFO,3.9,SAMPLE_MASS
INFO,,SAMPLE_VOLUME
INFO,,SAMPLE_MOLECULAR_WEIGHT
INFO,,SAMPLE_SIZE
INFO,,SAMPLE_SHAPE
INFO,Straw,SAMPLE_HOLDER
INFO,Standard,SAMPLE_HOLDER_DETAIL
INFO,57.92,SAMPLE_OFFSET
DATATYPE,COMMENT,1
DATATYPE,TIME,2
STARTUPAXIS,X,3
STARTUPAXIS,Y1,4
STARTUPAXIS,Y2,5
STARTUPAXIS,Y2,6
STARTUPAXIS,Y2,7
STARTUPAXIS,Y3,8
STARTUPAXIS,Y3,9
RECORDS,FROM_TO_RECORDS,1,604
[Data]
Comment,Time Stamp (sec),Raw Position (mm),Raw Voltage (V),Processed Voltage (V),Fixed C Fitted (V),Free C Fitted (V)
;low temp = 299.988861083984 K;high temp = 300.017883300781 K;avg. temp = 300.005017089844 K;low field = 10000.087890625 Oe;high field = 10000.087890625 Oe;drift = -0.000348449193552369 V/s;slope = -4.64598924736492E-5 V/mm;squid range = 1000;given center = 39.8807718010126 mm;calculated center = 39.8678207397461 mm;amp fixed = 2.49162817001343 V;amp free =2.49108910560608 V
,3720425238.51308,24.9415168762207,-0.376640230417252,-0.0377388522028923
,3720425238.53308,25.0900001525879,-0.381271362304687,-0.0423630848526955
,3720425238.55308,25.2387886047363,-0.385860830545425,-0.0469456426799297
,3720425238.57308,25.3880290985107,-0.391018927097321,-0.0520968027412891
,3720425238.59308,25.5368194580078,-0.39609357714653,-0.0571645423769951
,3720425238.61308,25.6856060028076,-0.401586711406708,-0.0626507624983788
,3720425238.63308,25.8348484039307,-0.40766429901123,-0.0687214136123657
,3720425238.65308,25.9836349487305,-0.413239032030106,-0.0742892399430275
,3720425238.67308,26.1324234008789,-0.419993907213211,-0.081037200987339
,3720425238.69308,26.2816677093506,-0.426411420106888,-0.08744777739048
,3720425238.71308,26.4303035736084,-0.433472990989685,-0.0945024415850639
,3720425238.73308,26.5789413452148,-0.440503865480423,-0.101526409387589
,3720425238.75308,26.7287883758545,-0.447785824537277,-0.108801409602165
,3720425238.77308,26.8774242401123,-0.455517143011093,-0.116525821387768
,3720425238.79308,27.0271224975586,-0.463103622198105,-0.124105349183083
,3720425238.81308,27.1771221160889,-0.471161931753159,-0.132156684994698
,3720425238.83308,27.3271217346191,-0.479158878326416,-0.140146657824516
,3720425238.85308,27.4754543304443,-0.486998021602631,-0.147978916764259
,3720425238.87308,27.6245460510254,-0.495255142450333,-0.156229108572006
,3720425238.89308,27.7728786468506,-0.503117680549622,-0.164084762334824
,3720425238.91308,27.9218196868896,-0.511070609092712,-0.172030761837959
,3720425238.93308,28.0695457458496,-0.518718242645264,-0.179671540856361
,3720425238.95308,28.2190914154053,-0.526572406291962,-0.187518745660782
,3720425238.97308,28.3683319091797,-0.534277975559235,-0.1952173858881
,3720425238.99308,28.5159072875977,-0.541568696498871,-0.202501252293587
,3720425239.01308,28.6646976470947,-0.548551559448242,-0.209477201104164
,3720425239.03308,28.8133316040039,-0.555572628974915,-0.216491371393204
,3720425239.05308,28.962121963501,-0.561969041824341,-0.222880870103836
,3720425239.07308,29.1098480224609,-0.56818962097168,-0.229094579815865
,3720425239.09308,29.2584838867188,-0.573629915714264,-0.234527975320816
,3720425239.11308,29.4071216583252,-0.579100966453552,-0.23999211192131
,3720425239.13308,29.5551509857178,-0.583588004112244,-0.244472280144691
,3720425239.15308,29.7037887573242,-0.587822079658508,-0.248699441552162
,3720425239.17308,29.852575302124,-0.591685473918915,-0.252555936574936
,3720425239.19308,30.0006046295166,-0.594574749469757,-0.255438327789307
,3720425239.21308,30.149242401123,-0.597145974636078,-0.258002638816834
,3720425239.23308,30.2980289459229,-0.598760664463043,-0.259610414505005
,3720425239.25308,30.4471206665039,-0.600225985050201,-0.261068820953369
,3720425239.27308,30.5948486328125,-0.600661039352417,-0.261497020721436
,3720425239.29308,30.7434844970703,-0.600579142570496,-0.26140820980072
,3720425239.31308,30.8925762176514,-0.599630534648895,-0.260452657938004
,3720425239.33308,31.0407562255859,-0.598277747631073,-0.25909298658371
,3720425239.35308,31.1892433166504,-0.595980703830719,-0.256789058446884
,3720425239.37308,31.337272644043,-0.592969357967377,-0.25377082824707
,3720425239.39308,31.4856052398682,-0.589336037635803,-0.250130623579025
,3720425239.41308,31.6342430114746,-0.585321426391602,-0.24610909819603
,3720425239.43308,31.7830295562744,-0.579966485500336,-0.240747258067131
,3720425239.45308,31.9316673278809,-0.574379682540894,-0.235153540968895
,3720425239.47308,32.080150604248,-0.56771582365036,-0.228482782840729
,3720425239.49308,32.2290916442871,-0.560538411140442,-0.221298456192017
,3720425239.51308,32.3784828186035,-0.552628755569458,-0.213381856679916
,3720425239.53308,32.526668548584,-0.543776273727417,-0.204522490501404
,3720425239.55308,32.6746978759766,-0.534587323665619,-0.195326656103134
,3720425239.57308,32.8239402770996,-0.524222671985626,-0.184955075383186
,3720425239.59308,32.9725761413574,-0.513357818126678,-0.174083322286606
,3720425239.61308,33.1210594177246,-0.502097129821777,-0.162815734744072
,3720425239.63308,33.2693939208984,-0.489669859409332,-0.150381565093994
,3720425239.65308,33.4181823730469,-0.476724237203598,-0.137429028749466
,3720425239.67308,33.5660591125488,-0.463083922863007,-0.123781852424145
,3720425239.69308,33.7143936157227,-0.449115693569183,-0.109806731343269
,3720425239.71308,33.8636360168457,-0.434206068515778,-0.0948901697993278
,3720425239.73308,34.0125770568848,-0.418754488229752,-0.0794316679239273
,3720425239.75308,34.1612091064453,-0.402965068817139,-0.063635341823101
,3720425239.77308,34.3107566833496,-0.386573165655136,-0.0472364947199822
,3720425239.79308,34.4592437744141,-0.369671225547791,-0.0303276553750038
,3720425239.81308,34.6086349487305,-0.35217422246933,-0.0128237111493945
,3720425239.83308,34.7568206787109,-0.334628105163574,0.00472929142415524
,3720425239.85308,34.9057579040527,-0.316631257534027,0.0227330587804317
,3720425239.87308,35.0537872314453,-0.298293501138687,0.0410776920616627
,3720425239.89308,35.2019691467285,-0.279750496149063,0.0596275813877583
,3720425239.91308,35.3513641357422,-0.260922849178314,0.0784621685743332
,3720425239.93308,35.5004539489746,-0.241970285773277,0.0974216610193253
,3720425239.95308,35.6484832763672,-0.223496586084366,0.115902237594128
,3720425239.97308,35.796817779541,-0.204739779233932,0.134665936231613
,3720425239.99308,35.9454536437988,-0.186265125870705,0.153147488832474
,3720425240.01308,36.0927276611328,-0.168528109788895,0.170891359448433
,3720425240.03308,36.2410583496094,-0.15032659471035,0.189099758863449
,3720425240.05308,36.3901519775391,-0.133006811141968,0.206426471471786
,3720425240.07308,36.5384826660156,-0.115699604153633,0.223740562796593
,3720425240.09308,36.6863632202148,-0.099327988922596,0.240119054913521
,3720425240.11308,36.8356056213379,-0.0831272453069687,0.256326735019684
,3720425240.13308,36.9837875366211,-0.0682167261838913,0.271244138479233
,3720425240.15308,37.1316680908203,-0.053887877613306,0.285579860210419
,3720425240.17308,37.2803039550781,-0.0402474254369736,0.299227207899094
,3720425240.19308,37.4296989440918,-0.0273620188236237,0.312119573354721
,3720425240.21308,37.578483581543,-0.0150167420506477,0.324471741914749
,3720425240.23308,37.7272720336914,-0.00415092194452882,0.33534449338913
,3720425240.25308,37.8765144348145,0.00589036615565419,0.34539270401001
,3720425240.27308,38.0251502990723,0.0151988426223397,0.354708075523376
,3720425240.29308,38.1745452880859,0.0232328996062279,0.362749069929123
,3720425240.31308,38.3236351013184,0.0304935239255428,0.370016634464264
,3720425240.33308,38.4725761413574,0.0364599488675594,0.375989973545074
,3720425240.35308,38.620906829834,0.0415173657238483,0.381054282188416
,3720425240.37308,38.7692413330078,0.0455886535346508,0.38513246178627
,3720425240.39308,38.9177284240723,0.0485539846122265,0.38810470700264
,3720425240.41308,39.0660591125488,0.0506879016757011,0.390245497226715
,3720425240.43308,39.2154541015625,0.0516139417886734,0.391178488731384
,3720425240.45308,39.3633308410645,0.0516060292720795,0.391177445650101
,3720425240.47308,39.5116691589355,0.0506250821053982,0.390203386545181
,3720425240.49308,39.6599998474121,0.0487251207232475,0.388310313224793
,3720425240.51308,39.8084831237793,0.0460338443517685,0.385625928640366
,3720425240.53308,39.957878112793,0.0423187762498856,0.381917804479599
,3720425240.55308,40.1062126159668,0.0379106178879738,0.377516537904739
,3720425240.57308,40.254093170166,0.0326778888702393,0.372290700674057
,3720425240.59308,40.4030303955078,0.0266185142099857,0.366238236427307
,3720425240.61308,40.5518188476562,0.0202021300792694,0.359828770160675
,3720425240.63308,40.7003021240234,0.0124051542952657,0.352038681507111
,3720425240.65308,40.8493957519531,0.00466937432065606,0.344309836626053
,3720425240.67308,40.9978790283203,-0.00407480867579579,0.33557254076004
,3720425240.69308,41.1463623046875,-0.0135148847475648,0.326139360666275
,3720425240.71308,41.2945442199707,-0.0229873098433018,0.316673815250397
,3720425240.73308,41.4428825378418,-0.0336250066757202,0.306043028831482
,3720425240.75308,41.5921173095703,-0.0442351028323174,0.295439869165421
,3720425240.77308,41.7401504516602,-0.0553619898855686,0.284319847822189
,3720425240.79308,41.8889389038086,-0.067170575261116,0.272518187761307
,3720425240.81308,42.0366668701172,-0.0789256095886231,0.260769993066788
,3720425240.83308,42.1860580444336,-0.0915584489703178,0.24814410507679
,3720425240.85308,42.3340911865234,-0.104042693972588,0.235666736960411
,3720425240.87308,42.4828796386719,-0.11700577288866,0.222710579633713
,3720425240.89308,42.6312103271484,-0.130335241556168,0.209388002753258
,3720425240.91308,42.7799987792969,-0.14323765039444,0.19649250805378
,3720425240.93308,42.9289398193359,-0.156888112425804,0.182848960161209
,3720425240.95308,43.077579498291,-0.170490235090256,0.16925373673439
,3720425240.97308,43.2265129089355,-0.184424743056297,0.155326157808304
,3720425240.99308,43.3745460510254,-0.198147416114807,0.141610354185104
,3720425241.01308,43.5237884521484,-0.212068200111389,0.127696514129639
,3720425241.03308,43.6719665527344,-0.225614979863167,0.114156611263752
,3720425241.05308,43.8212127685547,-0.239098772406578,0.100679755210876
,3720425241.07308,43.9692420959473,-0.252539902925491,0.0872455015778542
,3720425241.09308,44.1181831359863,-0.265755474567413,0.0740368515253067
,3720425241.11308,44.2660598754883,-0.278978526592255,0.0608206689357758
,3720425241.13308,44.4156036376953,-0.292036086320877,0.0477700568735599
,3720425241.15308,44.564697265625,-0.304245918989182,0.0355671495199204
,3720425241.17308,44.7131843566895,-0.316413581371307,0.0234063863754272
,3720425241.19308,44.861515045166,-0.328207492828369,0.0116193667054176
,3720425241.21308,45.0107574462891,-0.339478552341461,0.000355240917997435
,3720425241.23308,45.1596984863281,-0.350657284259796,-0.010816571302712
,3720425241.25308,45.3069686889648,-0.360965639352798,-0.0211180839687586
,3720425241.27308,45.4559097290039,-0.371014297008514,-0.0311598218977451
,3720425241.29308,45.6045455932617,-0.380322813987732,-0.0404614321887493
,3720425241.31308,45.7533340454102,-0.389544546604156,-0.0496762543916702
,3720425241.33308,45.9012107849121,-0.397817730903625,-0.0579425655305386
,3720425241.35308,46.0501518249512,-0.405632466077805,-0.0657503828406334
,3720425241.37308,46.1993942260742,-0.412851810455322,-0.0729627907276154
,3720425241.39308,46.3474235534668,-0.419517815113068,-0.0796219184994698
,3720425241.41308,46.4965133666992,-0.42583292722702,-0.0859301090240478
,3720425241.43308,46.6445465087891,-0.431174039840698,-0.0912643373012543
,3720425241.45308,46.7934875488281,-0.436342716217041,-0.0964260995388031
,3720425241.47308,46.9413604736328,-0.441167831420898,-0.10124434530735
,3720425241.49308,47.0904541015625,-0.44504725933075,-0.105116844177246
,3720425241.51308,47.2387886047363,-0.448679059743881,-0.108741752803326
,3720425241.53308,47.387882232666,-0.45164293050766,-0.111698694527149
,3720425241.55308,47.5362091064453,-0.454182088375092,-0.114230960607529
,3720425241.57308,47.6851501464844,-0.456284731626511,-0.116326689720154
,3720425241.59308,47.8331832885742,-0.457685351371765,-0.117720425128937
,3720425241.61308,47.9816665649414,-0.459391087293625,-0.119419269263744
,3720425241.63308,48.1301498413086,-0.45984736084938,-0.119868643581867
,3720425241.65308,48.2784881591797,-0.460690975189209,-0.120705366134644
,3720425241.67308,48.4274215698242,-0.460856109857559,-0.120863579213619
,3720425241.69308,48.5760612487793,-0.460777789354324,-0.120778352022171
,3720425241.71308,48.7242431640625,-0.460800230503082,-0.120793908834457
,3720425241.73308,48.8728790283203,-0.460144102573395,-0.120130874216557
,3720425241.75308,49.0215148925781,-0.459344893693924,-0.119324758648872
,3720425241.77308,49.1699981689453,-0.458183079957962,-0.118156045675278
,3720425241.79308,49.3189392089844,-0.456886798143387,-0.116852849721909
,3720425241.81308,49.4674224853516,-0.455651521682739,-0.115610674023628
,3720425241.83308,49.6160583496094,-0.454064965248108,-0.114017210900784
,3720425241.85308,49.7646980285645,-0.452669829130173,-0.112615168094635
,3720425241.87308,49.9128799438477,-0.450846523046494,-0.110784977674484
,3720425241.89308,50.0613632202148,-0.4488705098629,-0.108802065253258
,3720425241.91308,50.2103042602539,-0.447016328573227,-0.10694096237421
,3720425241.93308,50.3586387634277,-0.444850087165833,-0.104767829179764
,3720425241.95308,50.5072708129883,-0.443120807409287,-0.103031650185585
,3720425241.97308,50.6559066772461,-0.440911620855331,-0.100815556943417
,3720425241.99308,50.8040924072266,-0.438811004161835,-0.0987080559134483
,3720425242.01308,50.9521179199219,-0.436534583568573,-0.0964247584342957
,3720425242.03308,51.1012115478516,-0.434253692626953,-0.0941369384527206
,3720425242.05308,51.2498474121094,-0.432124584913254,-0.0920009240508079
,3720425242.07308,51.3977279663086,-0.429982423782349,-0.0898518934845924
,3720425242.09308,51.5462112426758,-0.427519083023071,-0.0873816534876823
,3720425242.11308,51.6954536437988,-0.425548374652863,-0.0854040086269379
,3720425242.13308,51.8428802490234,-0.423275619745255,-0.0831244066357613
,3720425242.15308,51.991512298584,-0.421000391244888,-0.0808422714471817
,3720425242.17308,52.1398468017578,-0.418955773115158,-0.0787907615303993
,3720425242.19308,52.2886390686035,-0.417073130607605,-0.0769012048840523
,3720425242.21308,52.4372711181641,-0.414723813533783,-0.0745449885725975
,3720425242.23308,52.5857582092285,-0.412941306829453,-0.0727555826306343
,3720425242.25308,52.7343940734863,-0.41077932715416,-0.070586696267128
,3720425242.27308,52.8828811645508,-0.40903440117836,-0.0688348710536957
,3720425242.29308,53.0309066772461,-0.406856268644333,-0.0666498616337776
,3720425242.31308,53.1800003051758,-0.405251652002335,-0.0650383159518242
,3720425242.33308,53.328182220459,-0.403740227222443,-0.0635200068354607
,3720425242.35308,53.4765129089355,-0.401837974786758,-0.0616108626127243
,3720425242.37308,53.6257553100586,-0.400087982416153,-0.0598539374768734
,3720425242.39308,53.7743949890137,-0.398332357406616,-0.0580914057791233
,3720425242.41308,53.9225769042969,-0.396661788225174,-0.0564139522612095
,3720425242.43308,54.0710601806641,-0.395254611968994,-0.0549998767673969
,3720425242.45308,54.2201499938965,-0.39357602596283,-0.0533143654465675
,3720425242.47308,54.3677291870117,-0.392009019851685,-0.051740501075983
,3720425242.49308,54.5160598754883,-0.390650421380997,-0.0503750145435333
,3720425242.51308,54.6643943786621,-0.389028459787369,-0.0487461611628532
;low temp = 299.988861083984 K;high temp = 300.017883300781 K;avg. temp = 300.005017089844 K;low field = 10000.087890625 Oe;high field = 10000.087890625 Oe;drift = -0.000348449193552369 V/s;slope = 4.64598924736492E-5 V/mm;squid range = 1000;given center = 39.8807718010126 mm;calculated center = 39.8678207397461 mm;amp fixed = 2.49162817001343 V;amp free =2.49108910560608 V
,3720425243.87761,54.8069686889648,-0.386531800031662,-0.0465082190930843
,3720425243.89761,54.6575775146484,-0.388140201568604,-0.0481096804141998
,3720425243.91761,54.5077285766602,-0.389380574226379,-0.0493430905044079
,3720425243.93761,54.3581848144531,-0.391026556491852,-0.0509821251034737
,3720425243.95761,54.2090911865234,-0.39243084192276,-0.0523794814944267
,3720425243.97761,54.0590934753418,-0.394544154405594,-0.0544858276844025
,3720425243.99761,53.9101524353027,-0.39606574177742,-0.0560004934668541
,3720425244.01761,53.7612113952637,-0.39782303571701,-0.0577508695423603
,3720425244.03761,53.6116638183594,-0.399589419364929,-0.0595103055238724
,3720425244.05761,53.4627304077148,-0.40133398771286,-0.0612479522824287
,3720425244.07761,53.3142433166504,-0.403195828199387,-0.0631028935313225
,3720425244.09761,53.1656036376953,-0.405057013034821,-0.0649571716785431
,3720425244.11761,53.0171203613281,-0.406982988119125,-0.0668762475252152
,3720425244.13761,52.8690910339355,-0.408908993005753,-0.0687953755259514
,3720425244.15761,52.7201499938965,-0.41093048453331,-0.0708099529147148
,3720425244.17761,52.571361541748,-0.413123190402985,-0.0729957446455955
,3720425244.19761,52.4231834411621,-0.415105223655701,-0.0749708935618401
,3720425244.21761,52.2751502990723,-0.417136520147324,-0.076995313167572
,3720425244.23761,52.1251525878906,-0.419505894184113,-0.0793577134609222
,3720425244.25761,51.9768180847168,-0.42127737402916,-0.0811223015189171
,3720425244.27761,51.8283348083496,-0.423764318227768,-0.0836023464798927
,3720425244.29761,51.6803016662598,-0.425729602575302,-0.0855607539415359
,3720425244.31761,51.5299987792969,-0.428308099508286,-0.0881322696805
,3720425244.33761,51.3821182250977,-0.43061426281929,-0.0904315635561943
,3720425244.35761,51.2342414855957,-0.432551562786102,-0.0923619940876961
,3720425244.37761,51.0854530334473,-0.434949547052383,-0.0947530642151833
,3720425244.39761,50.9362106323242,-0.437002152204514,-0.0967987328767777
,3720425244.41761,50.7880325317383,-0.439164400100708,-0.0989540964365005
,3720425244.43761,50.6396980285645,-0.441321581602097,-0.101104386150837
,3720425244.45761,50.4910583496094,-0.443082451820374,-0.102858349680901
,3720425244.47761,50.3425788879395,-0.445344597101212,-0.105113603174686
,3720425244.49761,50.1936378479004,-0.446974664926529,-0.106736749410629
,3720425244.51761,50.0456047058105,-0.449276089668274,-0.109031297266483
,3720425244.53761,49.8962097167969,-0.451001077890396,-0.110749341547489
,3720425244.55761,49.7478790283203,-0.452761679887772,-0.112503051757813
,3720425244.57761,49.5993957519531,-0.454753935337067,-0.114488407969475
,3720425244.59761,49.4489402770996,-0.456059008836746,-0.115786492824554
,3720425244.61761,49.3013610839844,-0.457578718662262,-0.117299348115921
,3720425244.63761,49.152271270752,-0.458533763885498,-0.118247464299202
,3720425244.65761,49.0033340454102,-0.45962530374527,-0.119332082569599
,3720425244.67761,48.8549995422363,-0.460434913635254,-0.120134800672531
,3720425244.69761,48.7068176269531,-0.460736483335495,-0.120429486036301
,3720425244.71761,48.558032989502,-0.461029082536697,-0.12071517854929
,3720425244.73761,48.4087905883789,-0.4612195789814,-0.120898738503456
,3720425244.75761,48.2604522705078,-0.460876792669296,-0.120549060404301
,3720425244.77761,48.1116638183594,-0.460127621889114,-0.119792975485325
,3720425244.79761,47.9630317687988,-0.458878457546234,-0.118536904454231
,3720425244.81761,47.814395904541,-0.457967072725296,-0.11761861294508
,3720425244.83761,47.6656036376953,-0.45642814040184,-0.116072773933411
,3720425244.85761,47.5166664123535,-0.454261988401413,-0.113899700343609
,3720425244.87761,47.3675765991211,-0.451681107282639,-0.111311890184879
,3720425244.89761,47.2187881469727,-0.448603868484497,-0.108227737247944
,3720425244.91761,47.0710601806641,-0.445128887891769,-0.104745894670486
,3720425244.93761,46.9219665527344,-0.440760940313339,-0.100371025502682
,3720425244.95761,46.7728805541992,-0.436084598302841,-0.0956877544522285
,3720425244.97761,46.624698638916,-0.431291282176971,-0.0908875539898872
,3720425244.99761,46.4760589599609,-0.425833940505981,-0.0854233056306839
,3720425245.01761,46.3272705078125,-0.419494837522507,-0.0790772885084152
,3720425245.03761,46.1784858703613,-0.412781029939652,-0.0723565667867661
,3720425245.05761,46.0301513671875,-0.405632972717285,-0.0652016177773476
,3720425245.07761,45.8812103271484,-0.39784649014473,-0.0574082173407078
,3720425245.09761,45.7325782775879,-0.389302730560303,-0.0488575547933578
,3720425245.11761,45.5842437744141,-0.380407691001892,-0.0399556234478951
,3720425245.13761,45.4363632202148,-0.370481640100479,-0.0300227012485266
,3720425245.15761,45.2872695922852,-0.361297398805618,-0.0208315327763557
,3720425245.17761,45.1390914916992,-0.350198447704315,-0.00972569733858109
,3720425245.19761,44.9896965026855,-0.339300721883774,0.00117896939627826
,3720425245.21761,44.8406066894531,-0.327625632286072,0.0128609854727983
,3720425245.23761,44.6931838989258,-0.316079318523407,0.0244141481816769
,3720425245.25761,44.5437889099121,-0.30397042632103,0.0365299805998802
,3720425245.27761,44.394847869873,-0.29136261343956,0.0491447150707245
,3720425245.29761,44.2462120056152,-0.278726577758789,0.0617876574397087
,3720425245.31761,44.0983352661133,-0.26563024520874,0.0748908594250679
,3720425245.33761,43.9503021240234,-0.252346456050873,0.0881815254688263
,3720425245.35761,43.8007583618164,-0.238875970244408,0.101658962666988
,3720425245.37761,43.6531829833984,-0.225571498274803,0.114970289170742
,3720425245.39761,43.5050010681152,-0.212026849389076,0.12852181494236
,3720425245.41761,43.3566665649414,-0.197962433099747,0.142593130469322
,3720425245.43761,43.2089385986328,-0.184045985341072,0.156516432762146
,3720425245.45761,43.060604095459,-0.170423313975334,0.170146003365517
,3720425245.47761,42.9116668701172,-0.156789541244507,0.183786690235138
,3720425245.49761,42.7639389038086,-0.143461376428604,0.197121724486351
,3720425245.51761,42.6157569885254,-0.129996225237846,0.21059376001358
,3720425245.53761,42.4675788879395,-0.117467150092125,0.223129719495773
,3720425245.55761,42.3180313110352,-0.104107104241848,0.236496716737747
,3720425245.57761,42.1695442199707,-0.0916596353054047,0.248951077461243
,3720425245.59761,42.0212097167969,-0.0794964954257011,0.26112112402916
,3720425245.61761,41.8721199035645,-0.0672333389520645,0.27339118719101
,3720425245.63761,41.7236366271973,-0.0560318566858768,0.28459957242012
,3720425245.65761,41.5743942260742,-0.0442483983933926,0.29638996720314
,3720425245.67761,41.4257583618164,-0.03334891051054,0.307296365499496
,3720425245.69761,41.2768173217773,-0.0231953114271164,0.317456871271133
,3720425245.71761,41.1281852722168,-0.0132593968883157,0.327399700880051
,3720425245.73761,40.9796981811523,-0.00427244324237108,0.336393564939499
,3720425245.75761,40.8309097290039,0.00447016814723611,0.34514307975769
,3720425245.77761,40.6822738647461,0.0122517719864845,0.352931588888168
,3720425245.79761,40.533634185791,0.0195122677832842,0.360198974609375
,3720425245.81761,40.3848495483398,0.0260067898780107,0.366700410842895
,3720425245.83761,40.2362098693848,0.0316905304789543,0.372391074895859
,3720425245.85761,40.0884857177734,0.0371029004454613,0.377810299396515
,3720425245.87761,39.9392433166504,0.0411228910088539,0.381837218999863
,3720425245.89761,39.7910614013672,0.0451780296862125,0.385899245738983
,3720425245.91761,39.6425743103027,0.048086266964674,0.388814389705658
,3720425245.93761,39.4946975708008,0.0497371889650822,0.390472173690796
,3720425245.95761,39.3460578918457,0.0506369322538376,0.391378819942474
,3720425245.97761,39.1969718933105,0.0505589917302132,0.391307801008225
,3720425245.99761,39.0489387512207,0.0492529645562172,0.3900086581707
,3720425246.01761,38.9006042480469,0.0471581518650055,0.387920737266541
,3720425246.03761,38.7525749206543,0.043816152960062,0.384585618972778
,3720425246.05761,38.6045455932617,0.0399800166487694,0.380756348371506
,3720425246.07761,38.4569702148438,0.0346792861819267,0.375462472438812
,3720425246.09761,38.3075752258301,0.0286475494503975,0.369437694549561
,3720425246.11761,38.1598472595215,0.0213783644139767,0.36217537522316
,3720425246.13761,38.0119705200195,0.0130023024976254,0.353806167840958
,3720425246.15761,37.8633308410645,0.00382011639885604,0.344630897045135
,3720425246.17761,37.713939666748,-0.0067338440567255,0.334083884954453
,3720425246.19761,37.564697265625,-0.0178618710488081,0.322962790727615
,3720425246.21761,37.4163665771484,-0.0299781057983637,0.310853451490402
,3720425246.23761,37.2686347961426,-0.0432202704250813,0.29761815071106
,3720425246.25761,37.1204528808594,-0.0568810626864433,0.283964246511459
,3720425246.27761,36.9719696044922,-0.0718727484345436,0.268979460000992
,3720425246.29761,36.8231811523438,-0.0870556458830833,0.253803461790085
,3720425246.31761,36.6740913391113,-0.103338696062565,0.237527340650558
,3720425246.33761,36.5260581970215,-0.119942620396614,0.2209302932024
,3720425246.35761,36.3771209716797,-0.137060269713402,0.203819558024406
,3720425246.37761,36.2286338806152,-0.155003815889359,0.185882911086082
,3720425246.39761,36.0803031921387,-0.172100782394409,0.168792843818665
,3720425246.41761,35.9318199157715,-0.190713539719582,0.150186985731125
,3720425246.43761,35.783031463623,-0.209085017442703,0.131822407245636
,3720425246.45761,35.6348495483398,-0.227615147829056,0.113299168646336
,3720425246.47761,35.4860610961914,-0.246292725205421,0.0946285054087639
,3720425246.49761,35.3374252319336,-0.26484802365303,0.0760801136493683
,3720425246.51761,35.1892433166504,-0.284007400274277,0.0569276176393032
,3720425246.53761,35.040454864502,-0.302398055791855,0.038543876260519
,3720425246.55761,34.8922729492188,-0.320473462343216,0.0204753540456295
,3720425246.57761,34.7430305480957,-0.338763356208801,0.00219239410944283
,3720425246.59761,34.5951499938965,-0.356139957904816,-0.0151773374527693
,3720425246.61761,34.4466667175293,-0.373513042926788,-0.0325435250997543
,3720425246.63761,34.2975769042969,-0.389716446399689,-0.0487399995326996
,3720425246.65761,34.149242401123,-0.406181693077087,-0.0651983544230461
,3720425246.67761,34.0006065368652,-0.422172218561172,-0.0811819732189178
,3720425246.69761,33.8516693115234,-0.43722328543663,-0.0962261259555817
,3720425246.71761,33.7036361694336,-0.452181875705719,-0.111177831888199
,3720425246.73761,33.5546989440918,-0.465968787670135,-0.124957829713821
,3720425246.75761,33.406665802002,-0.479853212833405,-0.138835370540619
,3720425246.77761,33.2586364746094,-0.492475986480713,-0.151451274752617
,3720425246.79761,33.109546661377,-0.504613935947418,-0.163582295179367
,3720425246.81761,32.9607582092285,-0.516412198543549,-0.175373643636703
,3720425246.83761,32.8124237060547,-0.526787638664246,-0.185742199420929
,3720425246.85761,32.6633338928223,-0.537214159965515,-0.196161791682243
,3720425246.87761,32.5149993896484,-0.545972645282745,-0.204913377761841
,3720425246.89761,32.3665161132812,-0.554439902305603,-0.213373735547066
,3720425246.91761,32.2175750732422,-0.562666594982147,-0.221593514084816
,3720425246.93761,32.0692443847656,-0.569601953029633,-0.228521972894669
,3720425246.95761,31.9206047058105,-0.576487898826599,-0.235401019454002
,3720425246.97761,31.772575378418,-0.582057356834412,-0.240963593125343
,3720425246.99761,31.6236343383789,-0.587335050106049,-0.246234372258186
,3720425247.01761,31.4756050109863,-0.591720402240753,-0.250612854957581
,3720425247.03761,31.3271217346191,-0.595060110092163,-0.253945648670197
,3720425247.05761,31.1786346435547,-0.598343908786774,-0.257222563028336
,3720425247.07761,31.0306053161621,-0.600283801555634,-0.259155571460724
,3720425247.09761,30.8821220397949,-0.602006018161774,-0.260870903730392
,3720425247.11761,30.7322731018066,-0.601985156536102,-0.260843068361282
,3720425247.13761,30.5837898254395,-0.601467907428742,-0.260318905115128
,3720425247.15761,30.4357566833496,-0.60124683380127,-0.260090976953506
,3720425247.17761,30.287878036499,-0.599851310253143,-0.258688569068909
,3720425247.19761,30.1384830474854,-0.597953975200653,-0.256784290075302
,3720425247.21761,29.9899997711182,-0.595493495464325,-0.254316926002502
,3720425247.23761,29.841516494751,-0.592504620552063,-0.251321136951447
,3720425247.25761,29.6930294036865,-0.589211463928223,-0.248021095991135
,3720425247.27761,29.5442428588867,-0.584492921829224,-0.243295639753342
,3720425247.29761,29.3963642120361,-0.580232977867127,-0.239028826355934
,3720425247.31761,29.2478790283203,-0.574682772159576,-0.233471721410751
,3720425247.33761,29.0983333587646,-0.568994045257568,-0.227776035666466
,3720425247.35761,28.9501514434814,-0.563070714473724,-0.22184582054615
,3720425247.37761,28.8018188476562,-0.556488633155823,-0.215256854891777
,3720425247.39761,28.6527271270752,-0.54990953207016,-0.208670824766159
,3720425247.41761,28.50439453125,-0.542381107807159,-0.201135516166687
,3720425247.43761,28.3549995422363,-0.53512567281723,-0.193873137235641
,3720425247.45761,28.2069702148438,-0.527692317962646,-0.186432898044586
,3720425247.47761,28.0584831237793,-0.519962668418884,-0.178696349263191
,3720425247.49761,27.9098491668701,-0.512288212776184,-0.171014994382858
,3720425247.51761,27.7612113952637,-0.504185914993286,-0.162905797362328
,3720425247.53761,27.6125755310059,-0.49622517824173,-0.154938146471977
,3720425247.55761,27.4642429351807,-0.488184213638306,-0.146890297532082
,3720425247.57761,27.3156051635742,-0.47995588183403,-0.138655051589012
,3720425247.59761,27.1666679382324,-0.472281873226166,-0.130974128842354
,3720425247.61761,27.018180847168,-0.463841080665588,-0.122526437044144
,3720425247.63761,26.8696975708008,-0.456829011440277,-0.1155074685812
,3720425247.65761,26.7213649749756,-0.448911339044571,-0.107582904398441
,3720425247.67761,26.5725765228271,-0.441764742136002,-0.100429393351078
,3720425247.69761,26.4240913391113,-0.434694975614548,-0.0933527275919914
,3720425247.71761,26.2757568359375,-0.427931666374207,-0.0865825265645981
,3720425247.73761,26.1271209716797,-0.421508550643921,-0.0801525041460991
,3720425247.75761,25.9786357879639,-0.41508761048317,-0.073724664747715
,3720425247.77761,25.8296966552734,-0.408788323402405,-0.0674184635281563
,3720425247.79761,25.6813640594482,-0.403521060943604,-0.0621443055570126
,3720425247.81761,25.5331802368164,-0.397470951080322,-0.0560873113572598
,3720425247.83761,25.3842430114746,-0.391930490732193,-0.0505399331450462
,3720425247.85761,25.2360591888428,-0.386245340108871,-0.0448478981852531
,3720425247.87761,25.0869693756104,-0.38178226351738,-0.0403778925538063
,3720425248.53117,24.8807716369629,,,-0.111422710120678,-0.11237621307373
,3720425248.55116,25.0307712554932,,,-0.113748244941235,-0.114718683063984
,3720425248.57116,25.1807708740234,,,-0.116114191710949,-0.117100656032562
,3720425248.59116,25.3307723999023,,,-0.118518121540546,-0.119519554078579
,3720425248.61116,25.4807720184326,,,-0.120957352221012,-0.121972531080246
,3720425248.63116,25.6307716369629,,,-0.123428650200367,-0.124456182122231
,3720425248.65116,25.7807712554932,,,-0.125928461551666,-0.126966759562492
,3720425248.67116,25.9307727813721,,,-0.128452748060226,-0.129500046372414
,3720425248.69116,26.0807723999023,,,-0.130996882915497,-0.132051199674606
,3720425248.71116,26.2307720184326,,,-0.133555874228477,-0.134615004062653
,3720425248.73116,26.3807716369629,,,-0.136124029755592,-0.137185513973236
,3720425248.75116,26.5307712554932,,,-0.138695135712624,-0.139756321907043
,3720425248.77116,26.6807727813721,,,-0.14126244187355,-0.14232037961483
,3720425248.79117,26.8307723999023,,,-0.14381842315197,-0.144869923591614
,3720425248.81117,26.9807720184326,,,-0.146355018019676,-0.147396609187126
,3720425248.83117,27.1307716369629,,,-0.148863479495049,-0.149891436100006
,3720425248.85117,27.2807712554932,,,-0.151334300637245,-0.152344569563866
,3720425248.87117,27.4307727813721,,,-0.153757378458977,-0.154745653271675
,3720425248.89117,27.5807723999023,,,-0.156121790409088,-0.157083481550217
,3720425248.91117,27.7307720184326,,,-0.158415988087654,-0.159346222877502
,3720425248.93117,27.8807716369629,,,-0.160627752542496,-0.161521345376968
,3720425248.95117,28.0307712554932,,,-0.16274406015873,-0.16359555721283
,3720425248.97117,28.1807727813721,,,-0.164751321077347,-0.165555015206337
,3720425248.99117,28.3307723999023,,,-0.166635200381279,-0.167385146021843
,3720425249.01117,28.4807720184326,,,-0.168380841612816,-0.169070810079575
,3720425249.03117,28.6307716369629,,,-0.169972807168961,-0.170596390962601
,3720425249.05116,28.7807712554932,,,-0.171395093202591,-0.171945676207542
,3720425249.07116,28.9307727813721,,,-0.172631293535233,-0.173102110624313
,3720425249.09116,29.0807723999023,,,-0.173664599657059,-0.174048721790314
,3720425249.11116,29.2307720184326,,,-0.17447791993618,-0.174768343567848
,3720425249.13116,29.3807716369629,,,-0.175053954124451,-0.175243616104126
,3720425249.15116,29.5307712554932,,,-0.175375282764435,-0.175457119941711
,3720425249.17116,29.6807727813721,,,-0.175424516201019,-0.175391465425491
,3720425249.19116,29.8307723999023,,,-0.175184369087219,-0.175029441714287
,3720425249.21116,29.9807720184326,,,-0.174637764692307,-0.174354135990143
,3720425249.23116,30.1307716369629,,,-0.173768028616905,-0.173349037766457
,3720425249.25116,30.2807712554932,,,-0.172558978199959,-0.171998202800751
,3720425249.27116,30.4307727813721,,,-0.170995056629181,-0.170286357402802
,3720425249.29117,30.5807723999023,,,-0.169061422348022,-0.168199017643929
,3720425249.31117,30.7307720184326,,,-0.166744217276573,-0.165722697973251
,3720425249.33117,30.8807716369629,,,-0.164030492305756,-0.16284491121769
,3720425249.35117,31.0307712554932,,,-0.160908564925194,-0.159554451704025
,3720425249.37117,31.1807727813721,,,-0.157367914915085,-0.155841365456581
,3720425249.39117,31.3307723999023,,,-0.153399378061295,-0.151697039604187
,3720425249.41117,31.4807720184326,,,-0.148995399475098,-0.147114560008049
,3720425249.43117,31.6307716369629,,,-0.144149765372276,-0.142088338732719
,3720425249.45117,31.7807712554932,,,-0.138858124613762,-0.136614724993706
,3720425249.47117,31.9307727813721,,,-0.133117645978928,-0.130691573023796
,3720425249.49117,32.0807723999023,,,-0.12692728638649,-0.124318562448025
,3720425249.51117,32.2307739257812,,,-0.120287626981735,-0.117496974766254
,3720425249.53117,32.3807716369629,,,-0.113201506435871,-0.110230401158333
,3720425249.55116,32.5307731628418,,,-0.105673111975193,-0.102523751556873
,3720425249.57116,32.6807708740234,,,-0.097708560526371,-0.0943838506937027
,3720425249.59116,32.8307723999023,,,-0.0893157571554184,-0.0858193337917328
,3720425249.61116,32.9807739257812,,,-0.0805041268467903,-0.0768403112888336
,3720425249.63116,33.1307716369629,,,-0.0712854787707329,-0.0674592703580856
,3720425249.65116,33.2807731628418,,,-0.0616726092994213,-0.0576896816492081
,3720425249.67116,33.4307708740234,,,-0.0516801625490189,-0.0475468188524246
,3720425249.69116,33.5807723999023,,,-0.0413243249058723,-0.0370474830269814
,3720425249.71116,33.7307739257812,,,-0.0306225102394819,-0.0262096673250198
,3720425249.73116,33.8807716369629,,,-0.0195943675935268,-0.0150535982102156
,3720425249.75116,34.0307731628418,,,-0.00826011691242456,-0.00360002391971648
,3720425249.77116,34.1807708740234,,,0.00335845910012722,0.00812875386327505
,3720425249.79117,34.3307723999023,,,0.0152383260428906,0.020109212026
,3720425249.81117,34.4807739257812,,,0.0273555740714073,0.032316979020834
,3720425249.83117,34.6307716369629,,,0.0396842397749424,0.0447256304323673
,3720425249.85117,34.7807731628418,,,0.0521981902420521,0.0573086217045784
,3720425249.87117,34.9307708740234,,,0.0648699700832367,0.0700380802154541
,3720425249.89117,35.0807723999023,,,0.077671118080616,0.082885168492794
,3720425249.91117,35.2307739257812,,,0.0905722603201866,0.0958201214671135
,3720425249.93117,35.3807716369629,,,0.103543438017368,0.108812630176544
,3720425249.95117,35.5307731628418,,,0.116552844643593,0.121830560266972
,3720425249.97117,35.6807708740234,,,0.129568859934807,0.134841978549957
,3720425249.99117,35.8307723999023,,,0.142558798193932,0.147813871502876
,3720425250.01117,35.9807739257812,,,0.155489206314087,0.16071255505085
,3720425250.03117,36.1307716369629,,,0.168326377868652,0.173504024744034
,3720425250.05116,36.2807731628418,,,0.181034997105598,0.186152786016464
,3720425250.07116,36.4307708740234,,,0.193580240011215,0.198623821139336
,3720425250.09116,36.5807723999023,,,0.205926537513733,0.210881382226944
,3720425250.11116,36.7307739257812,,,0.218037992715836,0.222889497876167
,3720425250.13116,36.8807716369629,,,0.229878783226013,0.23461227118969
,3720425250.15116,37.0307731628418,,,0.241412118077278,0.246012941002846
,3720425250.17116,37.1807708740234,,,0.252602159976959,0.257055729627609
,3720425250.19116,37.3307723999023,,,0.26341301202774,0.267704784870148
,3720425250.21116,37.4807739257812,,,0.27380907535553,0.277924805879593
,3720425250.23116,37.6307716369629,,,0.283755600452423,0.287681251764297
,3720425250.25116,37.7807731628418,,,0.293217837810516,0.296939790248871
,3720425250.27116,37.9307708740234,,,0.302162766456604,0.305667757987976
,3720425250.29117,38.0807723999023,,,0.310558199882507,0.313833564519882
,3720425250.31117,38.2307739257812,,,0.318373382091522,0.32140702009201
,3720425250.33117,38.3807716369629,,,0.325579315423965,0.328359812498093
,3720425250.35117,38.5307731628418,,,0.332148253917694,0.334665030241013
,3720425250.37117,38.6807708740234,,,0.338055044412613,0.340298384428024
,3720425250.39117,38.8307723999023,,,0.343276530504227,0.345237642526627
,3720425250.41117,38.9807739257812,,,0.347792029380798,0.349463194608688
,3720425250.43117,39.1307716369629,,,0.351583510637283,0.352958023548126
,3720425250.45117,39.2807731628418,,,0.354635417461395,0.355707824230194
,3720425250.47117,39.4307708740234,,,0.356935411691666,0.357701390981674
,3720425250.49117,39.5807723999023,,,0.358474045991898,0.358930557966232
,3720425250.51117,39.7307739257812,,,0.3592449426651,0.359390199184418
,3720425250.53117,39.8807716369629,,,0.3592449426651,0.359078407287598
,3720425250.55116,40.0307731628418,,,0.358474045991898,0.35799652338028
,3720425250.57116,40.1807708740234,,,0.356935411691666,0.356148988008499
,3720425250.59116,40.3307723999023,,,0.354635417461395,0.353543430566788
,3720425250.61116,40.4807739257812,,,0.351583510637283,0.35019052028656
,3720425250.63116,40.6307716369629,,,0.347792029380798,0.346103757619858
,3720425250.65116,40.7807731628418,,,0.343276530504227,0.341299921274185
,3720425250.67116,40.9307708740234,,,0.338055044412613,0.335798025131226
,3720425250.69116,41.0807723999023,,,0.332148253917694,0.329619795084
,3720425250.71116,41.2307739257812,,,0.325579345226288,0.322789311408997
,3720425250.73116,41.3807716369629,,,0.318373590707779,0.315332770347595
,3720425250.75116,41.5307731628418,,,0.31055822968483,0.30727806687355
,3720425250.77116,41.6807708740234,,,0.302162796258926,0.298655480146408
,3720425250.79117,41.8307723999023,,,0.293217867612839,0.289496183395386
,3720425250.81117,41.9807739257812,,,0.283755630254745,0.279832810163498
,3720425250.83117,42.1307716369629,,,0.273809343576431,0.269699066877365
,3720425250.85117,42.2807731628418,,,0.26341301202774,0.259129285812378
,3720425250.87117,42.4307708740234,,,0.252602189779282,0.248159229755402
,3720425250.89117,42.5807723999023,,,0.241412132978439,0.236824408173561
,3720425250.91117,42.7307739257812,,,0.229878798127174,0.225160822272301
,3720425250.93117,42.8807716369629,,,0.218038320541382,0.213204681873322
,3720425250.95117,43.0307731628418,,,0.205926567316055,0.200991854071617
[...]
,3720437343.54698,34.1210594177246,-0.341837733983994,-0.271369338035583
,3720437343.56698,33.9724235534668,-0.357046574354172,-0.286575824022293
,3720437343.58698,33.8230285644531,-0.371703565120697,-0.30123046040535
,3720437343.60698,33.6749992370605,-0.385166525840759,-0.314691096544266
,3720437343.62698,33.526969909668,-0.39800763130188,-0.32752987742424
,3720437343.64698,33.3778800964355,-0.409597903490067,-0.339117795228958
,3720437343.66698,33.2290916442871,-0.42047381401062,-0.349991351366043
,3720437343.68698,33.0804557800293,-0.430076479911804,-0.359591662883759
,3720437343.70698,32.9321212768555,-0.438832342624664,-0.368345201015472
,3720437343.72698,32.783332824707,-0.445966184139252,-0.375476688146591
,3720437343.74698,32.6349983215332,-0.452717512845993,-0.382225692272186
,3720437343.76698,32.4872741699219,-0.458002924919128,-0.387508749961853
,3720437343.78698,32.3383331298828,-0.462230920791626,-0.391734391450882
,3720437343.80698,32.1898498535156,-0.465570271015167,-0.395071417093277
,3720437343.82698,32.0407562255859,-0.467458873987198,-0.396957665681839
,3720437343.84698,31.893030166626,-0.468712210655212,-0.398208677768707
,3720437343.86698,31.7437896728516,-0.46869283914566,-0.398186951875687
,3720437343.88698,31.5953025817871,-0.467839062213898,-0.397330820560455
,3720437343.90698,31.4468193054199,-0.465869247913361,-0.395358681678772
,3720437343.92698,31.2978782653809,-0.463351607322693,-0.392838686704636
,3720437343.94698,31.1495456695557,-0.459528088569641,-0.389012813568115
,3720437343.96698,31.0010604858398,-0.454982608556747,-0.384465008974075
,3720437343.98698,30.8521213531494,-0.44946825504303,-0.378948301076889
,3720437344.00698,30.7037887573242,-0.443243384361267,-0.372721076011658
,3720437344.02698,30.5556049346924,-0.436080902814865,-0.36555626988411
,3720437344.04698,30.4068183898926,-0.428228884935379,-0.357701897621155
,3720437344.06698,30.2578792572022,-0.419902622699738,-0.349373281002045
,3720437344.08698,30.1101512908936,-0.410681188106537,-0.340149521827698
,3720437344.10698,29.9613647460937,-0.400711387395859,-0.330177366733551
,3720437344.12698,29.8121223449707,-0.390186041593552,-0.319649666547775
,3720437344.14698,29.6637897491455,-0.379294782876968,-0.308756083250046
,3720437344.16698,29.5151519775391,-0.367592662572861,-0.29705160856247
,3720437344.18698,29.3672733306885,-0.355828434228897,-0.28528505563736
,3720437344.20698,29.2177276611328,-0.342973232269287,-0.272427499294281
,3720437344.22698,29.0693950653076,-0.330020606517792,-0.259472519159317
,3720437344.24698,28.9212112426758,-0.316335767507553,-0.245785340666771
,3720437344.26698,28.7728786468506,-0.302772253751755,-0.232219487428665
,3720437344.28698,28.6239395141602,-0.289175450801849,-0.218620344996452
,3720437344.30698,28.475757598877,-0.27456995844841,-0.204012513160706
,3720437344.32698,28.3269710540771,-0.260050743818283,-0.18949094414711
,3720437344.34698,28.1780300140381,-0.245238214731216,-0.174676075577736
,3720437344.36698,28.0290908813477,-0.230135664343834,-0.159571170806885
,3720437344.38698,27.8812103271484,-0.215465366840363,-0.144898533821106
,3720437344.40698,27.7324237823486,-0.20026507973671,-0.129695907235146
,3720437344.42698,27.5837898254395,-0.185352563858032,-0.11478104442358
,3720437344.44698,27.435453414917,-0.170092806220055,-0.0995189473032951
,3720437344.46698,27.2871208190918,-0.155903652310371,-0.0853274539113045
,3720437344.48698,27.138635635376,-0.141107618808746,-0.070529080927372
,3720437344.50698,26.9901504516602,-0.126549065113068,-0.0559681840240955
,3720437344.52698,26.8422737121582,-0.112377233803272,-0.041794016957283
,3720437344.54698,26.6930294036865,-0.0984607636928558,-0.0278751943260431
,3720437344.56698,26.5442428588867,-0.0848897695541382,-0.0143018523231149
,3720437344.58698,26.3959083557129,-0.0717623755335808,-0.00117211847100407
,3720437344.60698,26.2472724914551,-0.0587616264820099,0.0118309753015637
,3720437344.62698,26.0989398956299,-0.0465256199240684,0.0240693222731352
,3720437344.64698,25.9498481750488,-0.0346658304333687,0.0359314642846584
,3720437344.66698,25.8013648986816,-0.0231353640556335,0.047464270144701
,3720437344.68698,25.6528778076172,-0.0121000865474343,0.0585018917918205
,3720437344.70698,25.504243850708,-0.00253247516229749,0.0680718496441841
,3720437344.72698,25.3562107086182,0.00744297727942467,0.0780496373772621
,3720437344.74698,25.2066669464111,0.0167218502610922,0.0873308703303337
,3720437344.76698,25.0580291748047,0.0253077186644077,0.0959190800786018
,3720437344.78698,24.9098491668701,0.0331629440188408,0.103776641190052
,3720437344.80698,24.7613639831543,0.0407001338899136,0.111316174268723
,3720437344.82698,24.6125755310059,0.047657385468483,0.11827577650547
,3720437344.84698,24.4642429351807,0.054033637046814,0.124654367566109
,3720437344.86698,24.3160591125488,0.0595530308783054,0.130176097154617
,3720437344.88698,24.167121887207,0.064614474773407,0.135239884257317
,3720437345.54827,23.9608955383301,,,-0.0592145062983036,-0.0661265701055527
,3720437345.56827,24.1108951568604,,,-0.0604503676295281,-0.0672918111085892
,3720437345.58827,24.2608947753906,,,-0.0617077052593231,-0.0684927105903625
,3720437345.60827,24.4108943939209,,,-0.0629852339625359,-0.0697299614548683
,3720437345.62827,24.5608959197998,,,-0.0642815157771111,-0.0710043162107468
,3720437345.64827,24.7108955383301,,,-0.0655948370695114,-0.0723163932561874
,3720437345.66827,24.8608951568604,,,-0.0669233202934265,-0.0736668333411217
,3720437345.68827,25.0108947753906,,,-0.0682648047804833,-0.0750562325119972
,3720437345.70827,25.1608943939209,,,-0.0696168467402458,-0.0764850676059723
,3720437345.72827,25.3108959197998,,,-0.0709767714142799,-0.0779538154602051
,3720437345.74827,25.4608955383301,,,-0.0723415687680244,-0.0794627964496613
,3720437345.76827,25.6108951568604,,,-0.0737079381942749,-0.0810123160481453
,3720437345.78827,25.7608947753906,,,-0.075072281062603,-0.0826025605201721
,3720437345.80827,25.9108943939209,,,-0.0764306113123894,-0.0842335447669029
,3720437345.82827,26.0608959197998,,,-0.0777786374092102,-0.0859052240848541
,3720437345.84827,26.2108955383301,,,-0.0791117176413536,-0.0876174047589302
,3720437345.86827,26.3608951568604,,,-0.0804247856140137,-0.0893696844577789
,3720437345.88827,26.5108947753906,,,-0.0817124843597412,-0.0911615565419197
,3720437345.90827,26.6608943939209,,,-0.0829690098762512,-0.0929922461509705
,3720437345.92827,26.8108959197998,,,-0.0841882228851318,-0.0948608219623566
,3720437345.94827,26.9608955383301,,,-0.0853636264801025,-0.0967661365866661
,3720437345.96827,27.1108951568604,,,-0.0864882916212082,-0.0987067222595215
,3720437345.98827,27.2608947753906,,,-0.0875550135970116,-0.10068091750145
,3720437346.00827,27.4108943939209,,,-0.088556170463562,-0.102686688303947
,3720437346.02827,27.5608959197998,,,-0.0894838571548462,-0.104721754789352
,3720437346.04827,27.7108955383301,,,-0.0903298780322075,-0.106783479452133
,3720437346.06827,27.8608951568604,,,-0.0910857245326042,-0.108868807554245
,3720437346.08827,28.0108947753906,,,-0.0917426869273186,-0.110974378883839
,3720437346.10827,28.1608943939209,,,-0.092291809618473,-0.113096326589584
,3720437346.12827,28.3108959197998,,,-0.0927240327000618,-0.115230418741703
,3720437346.14827,28.4608955383301,,,-0.0930301547050476,-0.11737197637558
,3720437346.16827,28.6108951568604,,,-0.0932009220123291,-0.119515731930733
,3720437346.18827,28.7608947753906,,,-0.0932270884513855,-0.121656015515327
,3720437346.20827,28.9108943939209,,,-0.0930994600057602,-0.123786613345146
,3720437346.22827,29.0608959197998,,,-0.0928089767694473,-0.125900700688362
,3720437346.24827,29.2108955383301,,,-0.0923467725515366,-0.127990990877151
,3720437346.26827,29.3608951568604,,,-0.0917042419314385,-0.130049511790276
,3720437346.28827,29.5108947753906,,,-0.0908731296658516,-0.132067799568176
,3720437346.30827,29.6608943939209,,,-0.0898455306887627,-0.134036794304848
,3720437346.32827,29.8108959197998,,,-0.0886140987277031,-0.135946795344353
,3720437346.34827,29.9608955383301,,,-0.0871719345450401,-0.13778755068779
,3720437346.36827,30.1108951568604,,,-0.0855128467082977,-0.139548227190971
,3720437346.38827,30.2608947753906,,,-0.083631232380867,-0.141217410564423
,3720437346.40827,30.4108963012695,,,-0.0815222263336182,-0.142783224582672
,3720437346.42827,30.5608959197998,,,-0.0791818052530289,-0.144233182072639
,3720437346.44827,30.7108955383301,,,-0.0766066834330559,-0.145554393529892
,3720437346.46827,30.8608951568604,,,-0.0737945362925529,-0.146733522415161
,3720437346.48827,31.0108947753906,,,-0.0707438588142395,-0.147756844758987
,3720437346.50827,31.1608963012695,,,-0.067454069852829,-0.148610383272171
,3720437346.52827,31.3108959197998,,,-0.0639256238937378,-0.149279817938805
,3720437346.54827,31.4608955383301,,,-0.060159794986248,-0.149750754237175
,3720437346.56827,31.6108951568604,,,-0.0561589673161507,-0.150008663535118
,3720437346.58827,31.7608947753906,,,-0.051926352083683,-0.150039032101631
,3720437346.60827,31.9108963012695,,,-0.047466091811657,-0.149827465415001
,3720437346.62827,32.0608940124512,,,-0.0427833683788776,-0.149359732866287
,3720437346.64827,32.2108955383301,,,-0.037884283810854,-0.148621961474419
,3720437346.66827,32.360897064209,,,-0.0327757000923157,-0.147600665688515
,3720437346.68827,32.5108947753906,,,-0.0274653974920511,-0.146282911300659
,3720437346.70827,32.6608963012695,,,-0.0219619777053595,-0.144656360149384
,3720437346.72827,32.8108940124512,,,-0.0162746924906969,-0.142709404230118
,3720437346.74827,32.9608955383301,,,-0.0104139894247055,-0.140431448817253
,3720437346.76827,33.110897064209,,,-0.00439060805365443,-0.137812688946724
,3720437346.78827,33.2608947753906,,,0.00178387120831758,-0.134844437241554
,3720437346.80827,33.4108963012695,,,0.00809720903635025,-0.131519138813019
,3720437346.82827,33.5608940124512,,,0.0145366992801428,-0.127830371260643
,3720437346.84827,33.7108955383301,,,0.0210885424166918,-0.123773291707039
,3720437346.86827,33.860897064209,,,0.0277388524264097,-0.119344152510166
,3720437346.88827,34.0108947753906,,,0.0344730354845524,-0.114540711045265
,3720437346.90827,34.1608963012695,,,0.0412759743630886,-0.109362155199051
,3720437346.92827,34.3108940124512,,,0.0481320507824421,-0.103809177875519
,3720437346.94827,34.4608955383301,,,0.0550253428518772,-0.0978837981820106
,3720437346.96827,34.610897064209,,,0.0619389526546001,-0.0915899947285652
,3720437346.98827,34.7608947753906,,,0.0688560754060745,-0.0849327966570854
,3720437347.00827,34.9108963012695,,,0.0757593363523483,-0.0779188573360443
,3720437347.02827,35.0608940124512,,,0.0826309695839882,-0.0705562904477119
,3720437347.04827,35.2108955383301,,,0.0894530490040779,-0.0628544390201569
,3720437347.06827,35.360897064209,,,0.0962068140506744,-0.0548246167600155
,3720437347.08827,35.5108947753906,,,0.102873750030994,-0.0464788861572742
,3720437347.10827,35.6608963012695,,,0.109434962272644,-0.0378308109939098
,3720437347.12827,35.8108940124512,,,0.115871369838715,-0.0288951862603426
,3720437347.14827,35.9608955383301,,,0.122163936495781,-0.0196877717971802
,3720437347.16827,36.110897064209,,,0.128293111920357,-0.0102261565625668
,3720437347.18827,36.2608947753906,,,0.134239867329597,-0.000528328469954431
,3720437347.20827,36.4108963012695,,,0.139985084533691,0.00938646402209997
,3720437347.22827,36.5608940124512,,,0.145509883761406,0.0194979831576347
,3720437347.24827,36.7108955383301,,,0.150795787572861,0.0297853108495474
,3720437347.26827,36.860897064209,,,0.155824318528175,0.0402258485555649
,3720437347.28827,37.0108947753906,,,0.160577923059463,0.050796914845705
,3720437347.30827,37.1608963012695,,,0.165039524435997,0.0614747554063797
,3720437347.32827,37.3108940124512,,,0.169192761182785,0.0722348317503929
,3720437347.34827,37.4608955383301,,,0.173022225499153,0.0830521285533905
,3720437347.36827,37.610897064209,,,0.176513165235519,0.0939001068472862
,3720437347.38827,37.7608947753906,,,0.179652214050293,0.104752376675606
,3720437347.40827,37.9108963012695,,,0.182427078485489,0.115581631660461
,3720437347.42827,38.0608940124512,,,0.184826746582985,0.126359984278679
,3720437347.44827,38.2108955383301,,,0.186841666698456,0.137059286236763
,3720437347.46827,38.360897064209,,,0.188463538885117,0.147650063037872
,3720437347.48827,38.5108947753906,,,0.189685836434364,0.158103287220001
,3720437347.50827,38.6608963012695,,,0.190503507852554,0.168389275670052
,3720437347.52827,38.8108940124512,,,0.190913200378418,0.178478062152863
,3720437347.54827,38.9608955383301,,,0.190913200378418,0.188339814543724
,3720437347.56827,39.110897064209,,,0.190503507852554,0.197943851351738
,3720437347.58827,39.2608947753906,,,0.189685821533203,0.207260280847549
,3720437347.60827,39.4108963012695,,,0.188463538885117,0.216259151697159
,3720437347.62827,39.5608940124512,,,0.186841651797295,0.224910870194435
,3720437347.64827,39.7108955383301,,,0.184826746582985,0.233186438679695
,3720437347.66827,39.860897064209,,,0.182427063584328,0.241056948900223
,3720437347.68827,40.0108947753906,,,0.179652199149132,0.248494848608971
,3720437347.70827,40.1608963012695,,,0.176513150334358,0.255473405122757
,3720437347.72827,40.3108940124512,,,0.173022210597992,0.261967033147812
,3720437347.74827,40.4608955383301,,,0.169192850589752,0.267951428890228
,3720437347.76827,40.610897064209,,,0.165039509534836,0.273404002189636
,3720437347.78827,40.7608947753906,,,0.160577908158302,0.278303414583206
,3720437347.80827,40.9108963012695,,,0.155824288725853,0.282630622386932
,3720437347.82827,41.0608940124512,,,0.150795757770538,0.286368399858475
,3720437347.84827,41.2108955383301,,,0.145509988069534,0.289501816034317
,3720437347.86827,41.360897064209,,,0.139985054731369,0.292018204927444
,3720437347.88827,41.5108947753906,,,0.134239837527275,0.293907165527344
,3720437347.90827,41.6608963012695,,,0.128293082118034,0.295161008834839
,3720437347.92827,41.8108940124512,,,0.122163906693459,0.295774549245834
,3720437347.94827,41.9608955383301,,,0.115871496498585,0.295745253562927
,3720437347.96827,42.110897064209,,,0.109434925019741,0.295073240995407
,3720437347.98827,42.2608947753906,,,0.102873712778091,0.293761283159256
,3720437348.00827,42.4108963012695,,,0.0962067767977715,0.291814833879471
,3720437348.02827,42.5608940124512,,,0.0894530117511749,0.289241820573807
,3720437348.04827,42.7108955383301,,,0.0826311036944389,0.286052823066711
,3720437348.06827,42.860897064209,,,0.0757592990994453,0.282260596752167
,3720437348.08827,43.0108947753906,,,0.0688560381531715,0.277880519628525
,3720437348.10827,43.1608963012695,,,0.0619389116764069,0.272929936647415
,3720437348.12827,43.3108940124512,,,0.0550253018736839,0.267428129911423
,3720437348.14827,43.4608955383301,,,0.0481321848928928,0.261396408081055
,3720437348.16827,43.610897064209,,,0.0412759371101856,0.254857420921326
,3720437348.18827,43.7608947753906,,,0.0344729982316494,0.24783593416214
,3720437348.20827,43.9108963012695,,,0.0277388151735067,0.240357488393784
,3720437348.22827,44.0608940124512,,,0.0210885051637888,0.232448950409889
,3720437348.24827,44.2108955383301,,,0.0145366620272398,0.224138110876083
,3720437348.26827,44.360897064209,,,0.00809717271476984,0.21545335650444
,3720437348.28827,44.5108947753906,,,0.00178383593447506,0.206424310803413
,3720437348.30827,44.6608963012695,,,-0.00439064251258969,0.197080448269844
,3720437348.32827,44.8108978271484,,,-0.0104140229523182,0.187451720237732
,3720437348.34827,44.9608955383301,,,-0.0162747260183096,0.177568256855011
,3720437348.36827,45.110897064209,,,-0.021962009370327,0.167460009455681
,3720437348.38827,45.2608947753906,,,-0.0274654272943735,0.157157555222511
,3720437348.40827,45.4108963012695,,,-0.0327757298946381,0.1466905772686
,3720437348.42827,45.5608978271484,,,-0.0378843136131763,0.136088714003563
,3720437348.44827,45.7108955383301,,,-0.0427833944559097,0.125381276011467
,3720437348.46827,45.860897064209,,,-0.0474661737680435,0.114596843719482
,3720437348.48827,46.0108947753906,,,-0.0519263744354248,0.103764347732067
,3720437348.50827,46.1608963012695,,,-0.0561589896678925,0.0929113551974297
,3720437348.52827,46.3108978271484,,,-0.0601598173379898,0.0820650979876518
,3720437348.54827,46.4608955383301,,,-0.063925601541996,0.0712521970272064
,3720437348.56827,46.610897064209,,,-0.0674540475010872,0.0604985728859901
,3720437348.58827,46.7608947753906,,,-0.0707438811659813,0.0498291812837124
,3720437348.60827,46.9108963012695,,,-0.0737945511937141,0.039269033819437
,3720437348.62827,47.0608978271484,,,-0.0766066983342171,0.0288415420800447
,3720437348.64827,47.2108955383301,,,-0.0791817903518677,0.0185695625841618
,3720437348.66827,47.360897064209,,,-0.081522211432457,0.0084750959649682
,3720437348.68827,47.5108947753906,,,-0.0836312398314476,-0.00142100942321122
,3720437348.70827,47.6608963012695,,,-0.0855128541588783,-0.0110981017351151
,3720437348.72827,47.8108978271484,,,-0.0871719419956207,-0.0205372776836157
,3720437348.74827,47.9608955383301,,,-0.0886140838265419,-0.0297204200178385
,3720437348.76827,48.110897064209,,,-0.0898455232381821,-0.0386305004358292
,3720437348.78827,48.2608947753906,,,-0.0908731296658516,-0.0472518503665924
,3720437348.80827,48.4108963012695,,,-0.091704249382019,-0.0555693469941616
,3720437348.82827,48.5608978271484,,,-0.0923467725515366,-0.0635697692632675
,3720437348.84827,48.7108955383301,,,-0.0928089767694473,-0.0712409690022469
,3720437348.86827,48.860897064209,,,-0.0930994600057602,-0.0785721614956856
,3720437348.88827,49.0108947753906,,,-0.0932270884513855,-0.0855540931224823
,3720437348.90827,49.1608963012695,,,-0.0932009220123291,-0.0921784490346909
,3720437348.92827,49.3108978271484,,,-0.0930301547050476,-0.0984388664364815
,3720437348.94827,49.4608955383301,,,-0.0927240401506424,-0.104330323636532
,3720437348.96827,49.610897064209,,,-0.0922918170690536,-0.109849274158478
,3720437348.98827,49.7608947753906,,,-0.0917426720261574,-0.114993795752525
,3720437349.00827,49.9108963012695,,,-0.0910857245326042,-0.11976308375597
,3720437349.02827,50.0608978271484,,,-0.0903298780322075,-0.124158218502998
,3720437349.04827,50.2108955383301,,,-0.0894838646054268,-0.12818156182766
,3720437349.06827,50.360897064209,,,-0.0885561779141426,-0.131836920976639
,3720437349.08827,50.5108947753906,,,-0.0875549986958504,-0.135129496455193
,3720437349.10827,50.6608963012695,,,-0.0864882841706276,-0.138065591454506
,3720437349.12827,50.8108978271484,,,-0.0853636190295219,-0.140652924776077
,3720437349.14827,50.9608955383301,,,-0.0841882303357124,-0.142900303006172
,3720437349.16827,51.110897064209,,,-0.0829690173268318,-0.14481757581234
,3720437349.18827,51.2608947753906,,,-0.0817124620079994,-0.146415546536446
,3720437349.20827,51.4108963012695,,,-0.0804247781634331,-0.147705778479576
,3720437349.22827,51.5608978271484,,,-0.079111710190773,-0.148700699210167
,3720437349.24827,51.7108955383301,,,-0.0777786448597908,-0.14941331744194
,3720437349.26827,51.860897064209,,,-0.07643061876297,-0.149857118725777
,3720437349.28827,52.0108947753906,,,-0.0750722587108612,-0.150046065449715
,3720437349.30827,52.1608963012695,,,-0.0737079307436943,-0.149994373321533
,3720437349.32827,52.3108978271484,,,-0.0723415613174439,-0.149716451764107
,3720437349.34827,52.4608955383301,,,-0.0709767639636993,-0.149226844310761
,3720437349.36827,52.610897064209,,,-0.0696168541908264,-0.148540034890175
,3720437349.38827,52.7608947753906,,,-0.0682648122310638,-0.147670477628708
,3720437349.40827,52.9108963012695,,,-0.0669233128428459,-0.146632343530655
,3720437349.42827,53.0608978271484,,,-0.0655948296189308,-0.145439729094505
,3720437349.44827,53.2108955383301,,,-0.0642815083265305,-0.14410625398159
,3720437349.46827,53.360897064209,,,-0.0629852414131165,-0.142645224928856
,3720437349.48827,53.5108947753906,,,-0.061707716435194,-0.141069501638412
,3720437349.50827,53.6608963012695,,,-0.0604503601789474,-0.139391452074051
,3720437349.52827,53.8108978271484,,,-0.059214498847723,-0.137623026967049