File: example_data/M20171121_Pd_one_torlon_M(T)_at_10000_Oe.dat
[Header]
; MPMS3 Data File (default extension .dat)
; Copyright (c) 2007, Quantum Design, Inc. All rights reserved.
TITLE,Pd with one Torlon
FILEOPENTIME,3720425186.1401,11/21/2017,11:27 am
BYAPP,SQUID AC,0.9.1.0
INFO,MPMS3 Measurement Release 1.1.16 Build 347, MultiVu Release 2.3.3.2,APPNAME
INFO,0,MOMENT_UNITS
INFO,Pd,SAMPLE_MATERIAL
INFO,Using only *one* torlon,SAMPLE_COMMENT
INFO,3.9,SAMPLE_MASS
INFO,,SAMPLE_VOLUME
INFO,,SAMPLE_MOLECULAR_WEIGHT
INFO,,SAMPLE_SIZE
INFO,,SAMPLE_SHAPE
INFO,Straw,SAMPLE_HOLDER
INFO,Standard,SAMPLE_HOLDER_DETAIL
INFO,57.92,SAMPLE_OFFSET
DATATYPE,COMMENT,1
DATATYPE,TIME,2
STARTUPAXIS,X,2
STARTUPAXIS,Y1,5
FIELDGROUP, VSM,2,3,4,5,6,8,9,10,11,14,15
FIELDGROUP, DC, 2,3,4,14,56,57,58,59,60,61,62,63,64,65,66,67,68,69
FIELDGROUP, AC, 2,3,4,11,16,17,18,19,20,21,22,23,24,25,26,27,28,29,30
STARTUPGROUP, All
[Data]
Comment,Time Stamp (sec),Temperature (K),Magnetic Field (Oe),Moment (emu),M. Std. Err. (emu),Transport Action,Averaging Time (sec),Frequency (Hz),Peak Amplitude (mm),Center Position (mm),Lockin Signal' (V),Lockin Signal (V),Range,M. Quad. Signal (emu),AC Moment (emu),AC M. Std Err. (emu),AC Phase (deg),AC Phase Std. Err. (deg),AC Susceptibility (emu/Oe),AC Suscept. Std Err. (emu/Oe),AC X' (emu/Oe),AC X' Std Err. (emu/Oe),AC X'' (emu/Oe),AC X'' Std Err. (emu/Oe),AC Drive (Oe),AC Frequency (Hz),AC Averaging Time (sec),AC Cycles,AC Range,AC Measure Type,AC Signal' (V),AC Signal'' (V),AC Trim Coil Ratio,AC Trim Coil Phase,Min. Temperature (K),Max. Temperature (K),Min. Field (Oe),Max. Field (Oe),Mass (grams),Motor Lag (deg),Pressure (Torr),Measure Count,Measurement Number,SQUID Status (code),Motor Status (code),Measure Status (code),Motor Current (amps),Motor Temp. (C),Temp. Status (code),Field Status (code),Chamber Status (code),Chamber Temp (K),Redirection State,Average Temp (K),Rotation Angle (deg),Rotator state,DC Moment Fixed Ctr (emu),DC Moment Err Fixed Ctr (emu),DC Moment Free Ctr (emu),DC Moment Err Free Ctr (emu),DC Fixed Fit,DC Free Fit,DC Calculated Center (mm),DC Calculated Center Err (mm),DC Scan Length (mm),DC Scan Time (s),DC Number of Points,DC Squid Drift,DC Min V (V),DC Max V (V),DC Scans per Measure,Map 01,Map 02,Map 03,Map 04,Map 05,Map 06,Map 07,Map 08,Map 09,Map 10,Map 11,Map 12,Map 13,Map 14,Map 15,Map 16
,3720425242.89997,300.005035400391,10000.087890625,,,6,,,,39.8807718010126,,,1,,,,,,,,,,,,,,,,,,,,,,299.988861083984,300.017883300781,10000.087890625,10000.087890625,,,6.97533464431763,-99999999,1,0,0,0,0,30.7917900085449,1,1,1,299.992797851562,0,300.005017089844,,,-0.000110668952354932,5.76002846183358E-6,-0.000110685618821174,5.76005749501533E-6,0.714137256145477,0.714605271816254,39.8198471069336,0.196989670395851,30,4,200,-0.00034844918991439,-0.602006018161774,0.0516139417886734,1,,,,,,,,,,,,,,,,
,3720425528.77017,291.704833984375,10000.087890625,,,6,,,,39.8443777130912,,,1,,,,,,,,,,,,,,,,,,,,,,291.688568115234,291.760314941406,10000.087890625,10000.087890625,,,6.97481060028076,-99999999,1,0,0,0,0,30.7917900085449,1,1,1,291.689147949219,0,291.729102240668,,,-0.000108184889054087,5.653903017717E-6,-0.000108224022246859,5.65399715038655E-6,0.701292097568512,0.702346265316009,39.9378929138184,0.197804003953934,30,4,200,-0.000635958567727357,-0.650602698326111,-0.00305686960928142,1,,,,,,,,,,,,,,,,
,3720425778.78514,283.749862670898,10000.087890625,,,6,,,,39.813528493238,,,1,,,,,,,,,,,,,,,,,,,,,,283.722930908203,283.808471679687,10000.087890625,10000.087890625,,,6.95292949676514,-99999999,1,0,0,0,0,30.7917900085449,1,1,1,283.723510742187,0,283.773681640625,,,-0.00010639188614346,5.5843683339636E-6,-0.000106470343960332,5.58454166044868E-6,0.68840092420578,0.690455257892609,39.9470825195313,0.19862562417984,30,4,200,-0.000462268944829702,-0.66761714220047,-0.0255201105028391,1,,,,,,,,,,,,,,,,
,3720426020.1011,275.810653686523,10000.087890625,,,6,,,,39.782976290683,,,1,,,,,,,,,,,,,,,,,,,,,,275.781921386719,275.872528076172,10000.087890625,10000.087890625,,,6.93110513687134,-99999999,1,0,0,0,0,30.7917900085449,1,1,1,275.786407470703,0,275.828559027778,,,-0.000104758565711764,5.52215988107921E-6,-0.000104885210247066,5.52243712367254E-6,0.676319897174835,0.679542362689972,39.9538497924805,0.199505284428597,30,4,200,7.54615484765964E-6,-0.681790769100189,-0.0451474711298943,1,,,,,,,,,,,,,,,,
,3720426259.31355,267.844100952148,10000.087890625,,,6,,,,39.7523934146984,,,1,,,,,,,,,,,,,,,,,,,,,,267.823394775391,267.898010253906,10000.087890625,10000.087890625,,,6.91102075576782,-99999999,1,0,0,0,0.013885498046875,30.7917900085449,1,1,1,267.82373046875,0,267.867757161458,,,-0.000102901304211165,5.45583699975722E-6,-0.000103117768226004,5.45632227421548E-6,0.66073203086853,0.666033029556274,39.977222442627,0.200666964054108,30,4,200,-0.000275589642114937,-0.696512877941132,-0.0635037496685982,1,,,,,,,,,,,,,,,,
,3720426486.98407,259.843475341797,10000.087890625,,,6,,,,39.7160409470499,,,1,,,,,,,,,,,,,,,,,,,,,,259.821472167969,259.889709472656,10000.087890625,10000.087890625,,,6.89008951187134,-99999999,1,0,0,0,0,30.7917900085449,1,1,1,259.830474853516,0,259.859456380208,,,-0.000101029380924535,5.3958219576236E-6,-0.000101383680334984,5.39665034947397E-6,0.642334699630737,0.650619447231293,40.0052337646484,0.202131316065788,30,4,200,0.000450473016826436,-0.70606917142868,-0.0777198076248169,1,,,,,,,,,,,,,,,,
,3720426729.82181,251.860687255859,10000.087890625,,,6,,,,39.6753647212342,,,1,,,,,,,,,,,,,,,,,,,,,,251.83723449707,251.919967651367,10000.087890625,10000.087890625,,,6.8651442527771,-99999999,1,0,0,0,0,30.3030319213867,1,1,1,251.840957641602,0,251.880839538574,,,-9.90388822366365E-5,5.33814707914264E-6,-9.9646149541819E-5,5.33951409867297E-6,0.6208655834198,0.63441276550293,40.0570793151855,0.204001232981682,30,4,200,3.83632650482468E-5,-0.721333205699921,-0.0958990976214409,1,,,,,,,,,,,,,,,,
,3720426973.2868,243.865043640137,10000.087890625,,,6,,,,39.6394200606254,,,1,,,,,,,,,,,,,,,,,,,,,,243.843566894531,243.912231445313,10000.087890625,10000.087890625,,,6.83819103240967,-99999999,1,0,0,0,0,30.7917900085449,1,1,1,243.848876953125,0,243.880596584744,,,-9.74869059764269E-5,5.30132234526304E-6,-9.84085827470617E-5,5.30333223686248E-6,0.601500272750855,0.62122505903244,40.1127395629883,0.205818012356758,30,4,200,-9.32799885049462E-5,-0.741550266742706,-0.117130115628242,1,,,,,,,,,,,,,,,,
,3720427205.38597,235.855361938477,10000.087890625,,,6,,,,39.6036867583839,,,1,,,,,,,,,,,,,,,,,,,,,,235.83479309082,235.901626586914,10000.087890625,10000.087890625,,,6.80952024459839,-99999999,1,0,0,0,0,30.7917900085449,1,1,1,235.837463378906,0,235.87316555447,,,-9.55742181988294E-5,5.25493362862937E-6,-9.68916824519471E-5,5.25787239262098E-6,0.579108655452728,0.605978786945343,40.1726760864258,0.208157509565353,30,4,200,-6.08955542702461E-6,-0.760820806026459,-0.139680847525597,1,,,,,,,,,,,,,,,,
,3720427441.00565,227.869407653809,10000.087890625,,,6,,,,39.5618477503485,,,1,,,,,,,,,,,,,,,,,,,,,,227.843292236328,227.911895751953,10000.087890625,10000.087890625,,,6.77876615524292,-99999999,1,0,0,0,0,29.8142719268799,1,1,1,227.856353759766,0,227.879406738281,,,-9.36015909344576E-5,5.21483489442612E-6,-9.54649245762113E-5,5.21899449249548E-6,0.554375052452087,0.590507030487061,40.2427177429199,0.21089580655098,30,4,200,-3.72640388377476E-5,-0.774049997329712,-0.154312402009964,1,,,,,,,,,,,,,,,,
,3720427675.444,219.867149353027,10000.087890625,,,6,,,,39.5202544263619,,,1,,,,,,,,,,,,,,,,,,,,,,219.8466796875,219.909225463867,10000.087890625,10000.087890625,,,6.74718141555786,-99999999,1,0,0,0,0,30.7917900085449,1,1,1,219.853820800781,0,219.879162597656,,,-9.18061822678164E-5,5.19182246038791E-6,-9.43008419339141E-5,5.19746696807416E-6,0.528638362884521,0.574420928955078,40.3116912841797,0.214088320732117,30,4,200,0.000431183696491644,-0.787263095378876,-0.168838411569595,1,,,,,,,,,,,,,,,,
,3720427909.18651,211.865348815918,10000.087890625,,,6,,,,39.4847700662975,,,1,,,,,,,,,,,,,,,,,,,,,,211.842025756836,211.904342651367,10000.087890625,10000.087890625,,,6.71596479415894,-99999999,1,0,0,0,0,30.3030319213867,1,1,1,211.845947265625,0,211.877755059136,,,-8.99869669315944E-5,5.17061736029309E-6,-9.3224359599948E-5,5.17785643431837E-6,0.503451406955719,0.559962570667267,40.391429901123,0.217555299401283,30,4,200,-0.000429761625127867,-0.802120506763458,-0.183753728866577,1,,,,,,,,,,,,,,,,
,3720428138.65064,203.864814758301,10000.087890625,,,6,,,,39.4441528956585,,,1,,,,,,,,,,,,,,,,,,,,,,203.834701538086,203.908065795898,10000.087890625,10000.087890625,,,6.6836314201355,-99999999,1,0,0,0,0,31.2805480957031,1,1,1,203.839141845703,0,203.875549316406,,,-8.81731195275986E-5,5.16254401993781E-6,-9.23202077168245E-5,5.17185732883684E-6,0.476202756166458,0.544629395008087,40.4749145507812,0.221691533923149,30,4,200,-0.000324419583193958,-0.814322292804718,-0.193717643618584,1,,,,,,,,,,,,,,,,
,3720428360.41157,195.876937866211,10000.087890625,,,6,,,,39.4079136258502,,,1,,,,,,,,,,,,,,,,,,,,,,195.847457885742,195.915664672852,10000.087890625,10000.087890625,,,6.64983177185059,-99999999,1,0,0,0,0,31.2805480957031,1,1,1,195.861145019531,0,195.884406195747,,,-8.63051534552948E-5,5.15209860466782E-6,-9.14299109352532E-5,5.16370128317654E-6,0.450489193201065,0.530831396579742,40.558666229248,0.226055398583412,30,4,200,0.000242007692577317,-0.826304733753204,-0.206079214811325,1,,,,,,,,,,,,,,,,
,3720428582.43698,187.880195617676,10000.087890625,,,6,,,,39.3723901129307,,,1,,,,,,,,,,,,,,,,,,,,,,187.859268188477,187.921966552734,10000.087890625,10000.087890625,,,6.61540603637695,-99999999,1,0,0,0,0,30.7917900085449,1,1,1,187.8671875,0,187.890930175781,,,-8.42983592649828E-5,5.15427000970808E-6,-9.0583975977044E-5,5.16847983897761E-6,0.421547114849091,0.514305949211121,40.6527519226074,0.231539323925972,30,4,200,1.63564836839214E-5,-0.836997449398041,-0.215710446238518,1,,,,,,,,,,,,,,,,
,3720428796.3959,179.87638092041,10000.087890625,,,6,,,,39.3365191144918,,,1,,,,,,,,,,,,,,,,,,,,,,179.8466796875,179.910354614258,10000.087890625,10000.087890625,,,6.58342456817627,-99999999,1,0,0,0,0,31.2805480957031,1,1,1,179.860824584961,0,179.881727430556,,,-8.23925853742885E-5,5.1718104701138E-6,-9.00174806641214E-5,5.18933222517066E-6,0.392828375101089,0.498524576425552,40.7513847351074,0.237764671444893,30,4,200,5.55167534912471E-5,-0.852402687072754,-0.228903397917747,1,,,,,,,,,,,,,,,,
,3720429010.59323,171.882751464844,10000.087890625,,,6,,,,39.3055497828694,,,1,,,,,,,,,,,,,,,,,,,,,,171.85514831543,171.918975830078,10000.087890625,10000.087890625,,,6.55065393447876,-99999999,1,0,0,0,0,30.7917900085449,1,1,1,171.876113891602,0,171.890897962782,,,-8.04424312191334E-5,5.19048074659535E-6,-8.9447590105572E-5,5.21142798041297E-6,0.365561544895172,0.483106017112732,40.8478546142578,0.244389623403549,30,4,200,-0.000153695917106234,-0.863727152347565,-0.236255645751953,1,,,,,,,,,,,,,,,,
,3720429218.74378,163.883018493652,10000.087890625,,,6,,,,39.2701061658546,,,1,,,,,,,,,,,,,,,,,,,,,,163.859466552734,163.911178588867,10000.087890625,10000.087890625,,,6.51863098144531,-99999999,1,0,0,0,0,30.7917900085449,1,1,1,163.879730224609,0,163.885157775879,,,-7.85053519339131E-5,5.22149524291963E-6,-8.90708481321168E-5,5.2463256159269E-6,0.338425248861313,0.468046486377716,40.9449844360352,0.251983076334,30,4,200,0.000161391857545823,-0.873019158840179,-0.244585528969765,1,,,,,,,,,,,,,,,,
,3720429434.1384,155.890480041504,10000.087890625,,,6,,,,39.2395840584108,,,1,,,,,,,,,,,,,,,,,,,,,,155.870971679687,155.920455932617,10000.087890625,10000.087890625,,,6.48337459564209,-99999999,1,0,0,0,0,30.7917900085449,1,1,1,155.885604858398,0,155.896814982096,,,-7.6701683723335E-5,5.25862368318861E-6,-8.88600704928935E-5,5.28750081368292E-6,0.313868761062622,0.454623639583588,41.0400848388672,0.259756088256836,30,4,200,-0.000250397773925215,-0.881299614906311,-0.247345179319382,1,,,,,,,,,,,,,,,,
,3720429637.65788,147.888122558594,10000.087890625,,,6,,,,39.2089027158902,,,1,,,,,,,,,,,,,,,,,,,,,,147.865707397461,147.914978027344,10000.087890625,10000.087890625,,,6.44669008255005,-99999999,1,0,0,0,0,30.7917900085449,1,1,1,147.881958007813,0,147.892150878906,,,-7.48666846506644E-5,5.30860916424417E-6,-8.88398772744888E-5,5.342174551539E-6,0.289193749427795,0.441381275653839,41.1412200927734,0.268720209598541,30,4,200,-0.000132422457681969,-0.890562534332275,-0.252195119857788,1,,,,,,,,,,,,,,,,
,3720429826.12943,139.869735717773,10000.087890625,,,6,,,,39.183171694562,,,1,,,,,,,,,,,,,,,,,,,,,,139.850845336914,139.890686035156,10000.087890625,10000.087890625,,,6.40811634063721,-99999999,1,0,0,0,0,31.2805480957031,1,1,1,139.869934082031,0,139.871303982205,,,-7.31671966393393E-5,5.36366456324084E-6,-8.89192769230723E-5,5.40210899236488E-6,0.26712629199028,0.429007649421692,41.2372093200684,0.277823567390442,30,4,200,0.000111661196569912,-0.899985492229462,-0.256342679262161,1,,,,,,,,,,,,,,,,
,3720430013.78105,131.88053894043,10000.087890625,,,6,,,,39.1579722242974,,,1,,,,,,,,,,,,,,,,,,,,,,131.8603515625,131.899108886719,10000.087890625,10000.087890625,,,6.3669114112854,-99999999,1,0,0,0,0,30.7917900085449,1,1,1,131.894577026367,0,131.879144287109,,,-7.13928644802486E-5,5.42556014247346E-6,-8.90589382796403E-5,5.46932653377135E-6,0.245493099093437,0.416536659002304,41.3341751098633,0.288074940443039,30,4,200,0.000617605284787714,-0.903068006038666,-0.255239635705948,1,,,,,,,,,,,,,,,,
,3720430162.1985,123.784210205078,10000.087890625,,,6,,,,39.1325731459618,,,1,,,,,,,,,,,,,,,,,,,,,,123.765319824219,123.799278259277,10000.087890625,10000.087890625,,,6.33134365081787,-99999999,1,0,0,0,0,30.7917900085449,1,1,1,123.803100585938,0,123.784038543701,,,-6.97884228955659E-5,5.48602574823734E-6,-8.93352870573419E-5,5.53502493057993E-6,0.227054297924042,0.406711637973785,41.4222183227539,0.297968149185181,30,4,200,-7.61754708946682E-5,-0.917008519172668,-0.259981840848923,1,,,,,,,,,,,,,,,,
,3720430306.16672,115.786819458008,10000.087890625,,,6,,,,39.1073633674849,,,1,,,,,,,,,,,,,,,,,,,,,,115.773101806641,115.796737670898,10000.087890625,10000.087890625,,,6.29871273040771,-99999999,1,0,0,0,0,30.7917900085449,1,1,1,115.800537109375,0,115.785096910265,,,-6.82439456580056E-5,5.55028794818549E-6,-8.97001484921865E-5,5.60526633407171E-6,0.2101089656353,0.397539675235748,41.5055656433105,0.308355093002319,30,4,200,-3.45085609296802E-5,-0.919186234474182,-0.255807340145111,1,,,,,,,,,,,,,,,,
,3720430449.75427,107.816146850586,10000.087890625,,,6,,,,39.0870148204541,,,1,,,,,,,,,,,,,,,,,,,,,,107.801597595215,107.827926635742,10000.087890625,10000.087890625,,,6.26662921905518,-99999999,1,0,0,0,0,30.7917900085449,1,1,1,107.830696105957,0,107.814294603136,,,-6.66037644379987E-5,5.60859207838185E-6,-8.99301600071606E-5,5.66881899065319E-6,0.194272711873054,0.388474464416504,41.5886726379395,0.319319278001785,30,4,200,0.000739132985472679,-0.918380975723267,-0.251390367746353,1,,,,,,,,,,,,,,,,
,3720430596.63973,99.816951751709,10000.087890625,,,6,,,,39.0667130047075,,,1,,,,,,,,,,,,,,,,,,,,,,99.8004913330078,99.8287887573242,10000.087890625,10000.087890625,,,6.23201131820679,-99999999,1,0,0,0,0.013885498046875,30.7917900085449,1,1,1,99.8334121704102,0,99.8119186401367,,,-6.50986470360502E-5,5.6739265413127E-6,-9.02625126502584E-5,5.73998371398224E-6,0.179911091923714,0.379621803760529,41.6653633117676,0.330541133880615,30,4,200,0.00093912536976859,-0.919099450111389,-0.244842007756233,1,,,,,,,,,,,,,,,,
,3720436480.24697,99.9514465332031,10000.3583984375,,,6,,,,39.1416959094564,,,1,,,,,,,,,,,,,,,,,,,,,,99.9386444091797,99.9607086181641,10000.3583984375,10000.3583984375,,,6.84277820587158,-99999999,1,0,0,0,0.013885498046875,31.2805480957031,1,1,1,99.9558258056641,0,99.9498206244575,,,-6.82295317183108E-5,5.98188942299554E-6,-9.46484221603375E-5,6.05423560509658E-6,0.17757984995842,0.373877167701721,41.8015899658203,0.33251690864563,30,4,200,0.146745249629021,-0.325148940086365,0.64395147562027,1,,,,,,,,,,,,,,,,
,3720436608.79128,92.8271636962891,10000.3583984375,,,6,,,,39.1061504916433,,,1,,,,,,,,,,,,,,,,,,,,,,92.799446105957,92.8364028930664,10000.3583984375,10000.3583984375,,,6.71235847473145,-99999999,1,0,0,0,0.013885498046875,30.7917900085449,1,1,1,92.8434906005859,0,92.8181321885851,,,-6.501906292266E-5,5.7311537346386E-6,-9.11145996846092E-5,5.79993805703125E-6,0.175477832555771,0.378637045621872,41.7502517700195,0.334281384944916,30,4,200,0.00531644187867641,-0.759910404682159,-0.0538338534533978,1,,,,,,,,,,,,,,,,
,3720436732.75442,85.7088165283203,10000.3583984375,,,6,,,,39.0527996654496,,,1,,,,,,,,,,,,,,,,,,,,,,85.6918411254883,85.7200317382813,10000.3583984375,10000.3583984375,,,6.56409358978271,-99999999,1,0,0,0,0,29.8142719268799,1,1,1,85.7185516357422,0,85.7050603230794,,,-6.35520402409667E-5,5.77655974538999E-6,-9.1442069462985E-5,5.8504901662565E-6,0.163990810513496,0.373652786016464,41.7846603393555,0.344737619161606,30,4,200,-3.12670708808582E-5,-0.485436886548996,0.193048447370529,1,,,,,,,,,,,,,,,,
,3720436848.26208,78.500301361084,10000.3583984375,,,6,,,,39.0167147244564,,,1,,,,,,,,,,,,,,,,,,,,,,78.4679107666016,78.4989395141602,10000.3583984375,10000.3583984375,,,6.38313674926758,-99999999,1,0,0,0,0,30.7917900085449,1,1,1,78.5105209350586,0,78.4844833374023,,,-6.23505769718758E-5,5.81889278256718E-6,-9.17479842644614E-5,5.89771505867224E-6,0.154784291982651,0.369130671024322,41.8203773498535,0.353956013917923,30,4,200,-0.000902912055607885,-0.452067166566849,0.235694974660873,1,,,,,,,,,,,,,,,,
,3720436968.73607,71.3456420898438,10000.3583984375,,,6,,,,38.9965546697442,,,1,,,,,,,,,,,,,,,,,,,,,,71.3317947387695,71.3498001098633,10000.3583984375,10000.3583984375,,,6.23810243606567,-99999999,1,0,0,0,0,30.3030319213867,1,1,1,71.359489440918,0,71.3419782850477,,,-6.13136171668283E-5,5.84194696425141E-6,-9.17121029137697E-5,5.92384348521013E-6,0.147951796650887,0.36457771062851,41.8502464294434,0.361409932374954,30,4,200,-0.000326382840285078,-0.466352224349976,0.22261805832386,1,,,,,,,,,,,,,,,,
,3720437089.63707,64.2301712036133,10000.3583984375,,,6,,,,38.9863912225703,,,1,,,,,,,,,,,,,,,,,,,,,,64.2199325561523,64.2330932617187,10000.3583984375,10000.3583984375,,,6.13091564178467,-99999999,1,0,0,0,0,30.3030319213867,1,1,1,64.2342987060547,0,64.2266303168403,,,-6.11455443901062E-5,5.88804375992158E-6,-9.22767272068266E-5,5.97249988452891E-6,0.144584000110626,0.362668067216873,41.8718147277832,0.365270346403122,30,4,200,0.000578139559365809,-0.476782828569412,0.213018909096718,1,,,,,,,,,,,,,,,,
,3720437210.8581,57.1130142211914,10000.3583984375,,,6,,,,38.9710297922114,,,1,,,,,,,,,,,,,,,,,,,,,,57.0990715026855,57.1258277893066,10000.3583984375,10000.3583984375,,,6.03984308242798,-99999999,1,0,0,0,0.013885498046875,30.7917900085449,1,1,1,57.1003913879395,0,57.1123229132758,,,-6.02037657801174E-5,5.92974510052081E-6,-9.25446589447865E-5,6.01841815646546E-6,0.137688249349594,0.358269780874252,41.9194297790527,0.373615801334381,30,4,200,0.000807601609267294,-0.475505858659744,0.219947800040245,1,,,,,,,,,,,,,,,,
,3720437340.00187,49.931755065918,10000.3583984375,,,6,,,,38.9608951130236,,,1,,,,,,,,,,,,,,,,,,,,,,49.919548034668,49.9420166015625,10000.3583984375,10000.3583984375,,,5.94057512283325,-99999999,1,0,0,0,0.013885498046875,30.7917900085449,1,1,1,49.9214935302734,0,49.9289300706651,,,-5.88129843749137E-5,5.94159378500198E-6,-9.22749347829233E-5,6.03401163873304E-6,0.13036385178566,0.353269815444946,41.9691047668457,0.383244246244431,30,4,200,-0.000118313226266764,-0.468712210655212,0.222438842058182,1,,,,,,,,,,,,,,,,