File: example_data/M20171121_Pd_one_torlon_M(T)_at_10000_Oe_background.rw.dat
[Header]
; DC Raw Data File (default extension .raw)
; Copyright 2012, Quantum Design, Inc. All rights reserved.
TITLE,Pd with one Torlon [Background Data]
FILEOPENTIME,3720439441.65891,11/21/2017,3:24 pm
BYAPP,SQUID AC,0.9.1.0
INFO,MPMS3 Option Release 1.1.16 Build 347, Release 2.3.3.2,APPNAME
INFO,TCI195,COIL_SERIAL_NUMBER
INFO,0,MOMENT_UNITS
INFO,Torlon,SAMPLE_MATERIAL
INFO,Background data: One Torlon offcentered, used in Pd with one Torlon,SAMPLE_COMMENT
INFO,,SAMPLE_MASS
INFO,,SAMPLE_VOLUME
INFO,,SAMPLE_MOLECULAR_WEIGHT
INFO,,SAMPLE_SIZE
INFO,,SAMPLE_SHAPE
INFO,Straw,SAMPLE_HOLDER
INFO,Standard,SAMPLE_HOLDER_DETAIL
INFO,57.92,SAMPLE_OFFSET
DATATYPE,COMMENT,1
DATATYPE,TIME,2
STARTUPAXIS,X,3
STARTUPAXIS,Y1,4
STARTUPAXIS,Y2,5
STARTUPAXIS,Y2,6
STARTUPAXIS,Y2,7
STARTUPAXIS,Y3,8
STARTUPAXIS,Y3,9
RECORDS,FROM_TO_RECORDS,1,604
[Data]
Comment,Time Stamp (sec),Raw Position (mm),Raw Voltage (V),Processed Voltage (V),Fixed C Fitted (V),Free C Fitted (V)
;low temp = 299.989044189453 K;high temp = 300.003753662109 K;avg. temp = 299.996813964844 K;low field = 10000.1865234375 Oe;high field = 10000.1865234375 Oe;drift = 0.118269603699446 V/s;slope = 0.0157692804932594 V/mm;squid range = 1000;given center = 39.6060001694262 mm;calculated center = 41.9691047668457 mm;amp fixed = 2.19978499412537 V;amp free =1.4020699262619 V
,3720439428.461,24.662878036499,-0.147077634930611,-0.41504380106926
,3720439428.481,24.8119697570801,-0.15061491727829,-0.420932173728943
,3720439428.501,24.9610595703125,-0.154405310750008,-0.42707359790802
,3720439428.521,25.1092433929443,-0.157516226172447,-0.432521253824234
,3720439428.541,25.2581806182861,-0.161041989922523,-0.438395649194717
,3720439428.561,25.4077262878418,-0.164140656590462,-0.443852543830872
,3720439428.581,25.556058883667,-0.167191848158836,-0.449242830276489
,3720439428.601,25.7048492431641,-0.169586032629013,-0.453983336687088
,3720439428.621,25.8537883758545,-0.172129780054092,-0.458875745534897
,3720439428.641,26.0036354064941,-0.173924133181572,-0.463033080101013
,3720439428.661,26.1521224975586,-0.175685048103333,-0.467135548591614
,3720439428.681,26.3021221160889,-0.176538616418838,-0.470354497432709
,3720439428.701,26.4516677856445,-0.177299693226814,-0.473473787307739
,3720439428.721,26.6010589599609,-0.177355423569679,-0.475885301828384
,3720439428.741,26.7496967315674,-0.177069023251534,-0.477942824363708
,3720439428.761,26.8987884521484,-0.175960555672646,-0.479185432195663
,3720439428.781,27.0478782653809,-0.174353152513504,-0.479929059743881
,3720439428.801,27.1966667175293,-0.17226667702198,-0.480188876390457
,3720439428.821,27.3445453643799,-0.169195115566254,-0.479449242353439
,3720439428.841,27.4942436218262,-0.165085539221764,-0.47770032286644
,3720439428.861,27.643180847168,-0.160466104745865,-0.475429505109787
,3720439428.881,27.7919692993164,-0.154755398631096,-0.472065091133118
,3720439428.901,27.9403018951416,-0.148305892944336,-0.467954695224762
,3720439428.921,28.0892429351807,-0.140571311116219,-0.462568789720535
,3720439428.941,28.2368183135986,-0.131985440850258,-0.456310093402863
,3720439428.961,28.3845462799072,-0.122063532471657,-0.44871774315834
,3720439428.981,28.533332824707,-0.111538164317608,-0.440538614988327
,3720439429.001,28.6816673278809,-0.0995908081531525,-0.430930405855179
,3720439429.021,28.8298492431641,-0.086847573518753,-0.420523881912231
,3720439429.041,28.9786357879639,-0.072638526558876,-0.408661097288132
,3720439429.061,29.1272735595703,-0.0574117265641689,-0.395778208971024
,3720439429.081,29.2754535675049,-0.0408449172973633,-0.381548076868057
,3720439429.101,29.4236354827881,-0.0231582298874855,-0.366198122501373
,3720439429.121,29.5731811523438,-0.00418457156047225,-0.349582701921463
,3720439429.141,29.7213649749756,0.0159720592200756,-0.331762820482254
,3720439429.161,29.8695449829102,0.0370417609810829,-0.313029795885086
,3720439429.181,30.0187892913818,0.0600246824324131,-0.292400360107422
,3720439429.201,30.167121887207,0.0833920314908028,-0.271372109651566
,3720439429.221,30.3156051635742,0.108213745057583,-0.248891860246658
,3720439429.241,30.4637889862061,0.13384585082531,-0.225596517324448
,3720439429.261,30.6124248504639,0.16090190410614,-0.200884342193604
,3720439429.281,30.7607574462891,0.188507452607155,-0.175617888569832
,3720439429.301,30.9099998474121,0.217536479234695,-0.148942306637764
,3720439429.321,31.0586357116699,0.247161686420441,-0.121660985052586
,3720439429.341,31.2069702148438,0.277948588132858,-0.0932132080197334
,3720439429.361,31.3549995422363,0.309339195489883,-0.0641569197177887
,3720439429.381,31.5037899017334,0.341569632291794,-0.0342727974057198
,3720439429.401,31.6525764465332,0.374524623155594,-0.00366406445391476
,3720439429.421,31.7999992370605,0.407588720321655,0.0270752813667059
,3720439429.441,31.9483318328857,0.441891640424728,0.0590391047298908
,3720439429.461,32.097728729248,0.476504445075989,0.091296024620533
,3720439429.481,32.2460594177246,0.511909425258636,0.12436193972826
,3720439429.501,32.3945465087891,0.547077000141144,0.157187983393669
,3720439429.521,32.5433311462402,0.583046972751617,0.190811723470688
,3720439429.541,32.6918182373047,0.619207978248596,0.224631190299988
,3720439429.561,32.8398475646973,0.655275166034698,0.258364081382751
,3720439429.581,32.9886360168457,0.691447794437408,0.292190402746201
,3720439429.601,33.1374244689941,0.727701008319855,0.326097339391708
,3720439429.621,33.2865142822266,0.764059782028198,0.360105067491531
,3720439429.641,33.4345474243164,0.799672663211822,0.39338356256485
,3720439429.661,33.5833320617676,0.83556741476059,0.426932096481323
,3720439429.681,33.731517791748,0.870737671852112,0.459765583276749
,3720439429.701,33.8804550170898,0.906088531017303,0.492767810821533
,3720439429.721,34.0284843444824,0.940296292304993,0.524641275405884
,3720439429.741,34.1777267456055,0.974374830722809,0.556366324424744
,3720439429.761,34.3265151977539,1.00764083862305,0.587286055088043
,3720439429.781,34.4748497009277,1.04043936729431,0.617745459079742
,3720439429.801,34.6240921020508,1.07183051109314,0.646783173084259
,3720439429.821,34.7724227905273,1.10246586799622,0.675079464912415
,3720439429.841,34.9212112426758,1.13190281391144,0.702170133590698
,3720439429.861,35.0698471069336,1.16025674343109,0.728180170059204
,3720439429.881,35.2190933227539,1.18741536140442,0.752985298633575
,3720439429.901,35.3668174743652,1.21310842037201,0.776348829269409
,3720439429.921,35.515453338623,1.23731482028961,0.798211336135864
,3720439429.941,35.6645469665527,1.26008355617523,0.818628966808319
,3720439429.961,35.8136367797852,1.28125584125519,0.837450206279755
,3720439429.981,35.9621200561523,1.30068504810333,0.854537963867187
,3720439430.001,36.1112098693848,1.31851279735565,0.870014667510986
,3720439430.021,36.2598495483398,1.33468091487885,0.883838832378387
,3720439430.041,36.408332824707,1.34855568408966,0.895372152328491
,3720439430.061,36.5577278137207,1.3605672121048,0.905027806758881
,3720439430.081,36.7060585021973,1.37048387527466,0.912605404853821
,3720439430.101,36.8548469543457,1.37875175476074,0.918527007102966
,3720439430.121,37.0022735595703,1.38462901115417,0.92207944393158
,3720439430.141,37.1515159606934,1.388707280159,0.92380428314209
,3720439430.161,37.2996978759766,1.39055478572845,0.923315048217773
,3720439430.181,37.4478797912598,1.39045417308807,0.920877695083618
,3720439430.201,37.5966682434082,1.3882040977478,0.916281342506409
,3720439430.221,37.7448501586914,1.38375318050385,0.909493744373321
,3720439430.241,37.8925743103027,1.37772834300995,0.901139378547668
,3720439430.261,38.0413665771484,1.36938118934631,0.89044588804245
,3720439430.281,38.189998626709,1.3596658706665,0.878386735916138
,3720439430.301,38.3390922546387,1.34745991230011,0.863829672336578
,3720439430.321,38.4883308410645,1.33393371105194,0.847950100898743
,3720439430.341,38.6375770568848,1.31826341152191,0.829926311969757
,3720439430.361,38.786060333252,1.30126774311066,0.810589134693146
,3720439430.381,38.9348487854004,1.28247547149658,0.789450585842133
,3720439430.401,39.0833320617676,1.26274240016937,0.767376065254211
,3720439430.421,39.2319717407227,1.24112951755524,0.743419229984283
,3720439430.441,39.3795471191406,1.21872842311859,0.718690991401672
,3720439430.461,39.5280303955078,1.19463729858398,0.692258358001709
,3720439430.481,39.6768188476562,1.16976416110992,0.66503894329071
,3720439430.501,39.8262100219727,1.14356088638306,0.63647985458374
,3720439430.521,39.9737892150879,1.11698031425476,0.607572078704834
,3720439430.541,40.1225738525391,1.08941459655762,0.577660143375397
,3720439430.561,40.2715148925781,1.06075882911682,0.546655654907227
,3720439430.581,40.4199981689453,1.03185224533081,0.515407621860504
,3720439430.601,40.568790435791,1.00242245197296,0.483631491661072
,3720439430.621,40.7175750732422,0.972289443016052,0.451152235269546
,3720439430.641,40.865909576416,0.942071735858917,0.418595403432846
,3720439430.661,41.0142440795898,0.911263823509216,0.38544836640358
,3720439430.681,41.1628799438477,0.880411207675934,0.352251887321472
,3720439430.701,41.3119659423828,0.849467098712921,0.318956792354584
,3720439430.721,41.4599990844727,0.818660795688629,0.285816103219986
,3720439430.741,41.609546661377,0.787683010101318,0.252480059862137
,3720439430.761,41.7583351135254,0.756924390792847,0.219375163316727
,3720439430.781,41.9060592651367,0.726536095142365,0.186657354235649
,3720439430.801,42.0546989440918,0.6965651512146,0.154342472553253
,3720439430.821,42.2030334472656,0.666799187660217,0.122237384319305
,3720439430.841,42.3516654968262,0.637324452400207,0.0904188305139542
,3720439430.861,42.5004539489746,0.608044564723969,0.0587926544249058
,3720439430.881,42.649242401123,0.579804420471191,0.0282062236219645
,3720439430.901,42.796817779541,0.55224072933197,-0.00168462563306093
,3720439430.921,42.9459075927734,0.525042057037354,-0.0312343370169401
,3720439430.941,43.0946960449219,0.498654335737228,-0.0599683448672295
,3720439430.961,43.2427291870117,0.473421514034271,-0.0875355452299118
,3720439430.981,43.3912124633789,0.44854924082756,-0.114749290049076
,3720439431.001,43.5403022766113,0.424696534872055,-0.140953034162521
,3720439431.021,43.6889419555664,0.401728063821793,-0.166265442967415
,3720439431.041,43.8375778198242,0.379860281944275,-0.190477102994919
,3720439431.061,43.9860610961914,0.359268665313721,-0.213410198688507
,3720439431.081,44.1348495483398,0.339558750391006,-0.235466405749321
,3720439431.101,44.2836380004883,0.320921212434769,-0.256450235843658
,3720439431.121,44.4318161010742,0.303581744432449,-0.276126354932785
,3720439431.141,44.5807571411133,0.286973297595978,-0.295083492994308
,3720439431.161,44.7295455932617,0.272001177072525,-0.3124018907547
,3720439431.181,44.8780326843262,0.257638514041901,-0.329106092453003
,3720439431.201,45.0265121459961,0.244912356138229,-0.344173669815063
,3720439431.221,45.1751518249512,0.233133032917976,-0.358296930789948
,3720439431.241,45.3239402770996,0.222721219062805,-0.371055036783218
,3720439431.261,45.4728813171387,0.213362097740173,-0.382762849330902
,3720439431.281,45.6210594177246,0.20528718829155,-0.393174439668655
,3720439431.301,45.7703018188477,0.198059797286987,-0.402755260467529
,3720439431.321,45.9187889099121,0.192304939031601,-0.410851657390594
,3720439431.341,46.066967010498,0.187449112534523,-0.418044149875641
,3720439431.361,46.2154541015625,0.183801144361496,-0.424033641815186
,3720439431.381,46.3648490905762,0.181192472577095,-0.428998172283173
,3720439431.401,46.51318359375,0.179746180772781,-0.432783603668213
,3720439431.421,46.6612091064453,0.178926885128021,-0.435937136411667
,3720439431.441,46.810604095459,0.179186895489693,-0.438032984733582
,3720439431.461,46.9587898254395,0.180396407842636,-0.439160257577896
,3720439431.481,47.1068153381348,0.182434305548668,-0.439456611871719
,3720439431.501,47.2556037902832,0.185304060578346,-0.43893313407898
,3720439431.521,47.4040908813477,0.188557341694832,-0.438021391630173
,3720439431.541,47.5524215698242,0.192944347858429,-0.435973465442657
,3720439431.561,47.7010612487793,0.197827160358429,-0.433434575796127
,3720439431.581,47.8501510620117,0.203259259462357,-0.43035352230072
,3720439431.601,47.9983367919922,0.209076061844826,-0.426873505115509
,3720439431.621,48.1468162536621,0.215956881642342,-0.422334104776382
,3720439431.641,48.2960586547852,0.22252906858921,-0.418115347623825
,3720439431.661,48.4442443847656,0.230078086256981,-0.412903130054474
,3720439431.681,48.5925788879395,0.237558513879776,-0.407761812210083
,3720439431.701,48.741512298584,0.245475560426712,-0.402193337678909
,3720439431.721,48.890453338623,0.253634572029114,-0.396383017301559
,3720439431.741,49.0383338928223,0.262198179960251,-0.390151381492615
,3720439431.761,49.1866645812988,0.270868837833405,-0.383819818496704
,3720439431.781,49.3353042602539,0.279721051454544,-0.377311527729034
,3720439431.801,49.4839401245117,0.288748264312744,-0.370628207921982
,3720439431.821,49.6324234008789,0.297771602869034,-0.363946348428726
,3720439431.841,49.7812118530273,0.307058691978455,-0.357005536556244
,3720439431.861,49.9304542541504,0.316277742385864,-0.350139915943146
,3720439431.881,50.0790901184082,0.325704336166382,-0.343057215213776
,3720439431.901,50.2268180847168,0.334907501935959,-0.336183607578278
,3720439431.921,50.375301361084,0.344209432601929,-0.329223155975342
,3720439431.941,50.5239410400391,0.353223115205765,-0.322553426027298
,3720439431.961,50.6719665527344,0.362493932247162,-0.315616846084595
,3720439431.981,50.8207550048828,0.371709942817688,-0.308747142553329
,3720439432.001,50.9695472717285,0.380606800317764,-0.302196621894836
,3720439432.021,51.1180305480957,0.389798492193222,-0.295346409082413
,3720439432.041,51.2660598754883,0.398717910051346,-0.288761287927628
,3720439432.061,51.4148483276367,0.407812267541885,-0.282013237476349
,3720439432.081,51.5628814697266,0.416283011436462,-0.275876849889755
,3720439432.101,51.7115135192871,0.425206542015076,-0.269297152757645
,3720439432.121,51.8606071472168,0.433503717184067,-0.263351082801819
,3720439432.141,52.008487701416,0.441966563463211,-0.257220208644867
,3720439432.161,52.1575775146484,0.450168520212173,-0.251369267702103
,3720439432.181,52.305908203125,0.458180457353592,-0.245696410536766
,3720439432.201,52.4546966552734,0.466204673051834,-0.240018486976624
,3720439432.221,52.6027297973633,0.473892033100128,-0.234665498137474
,3720439432.241,52.7518157958984,0.481827557086945,-0.229080960154533
,3720439432.261,52.9003028869629,0.489345967769623,-0.223904073238373
,3720439432.281,53.0489387512207,0.49690043926239,-0.218693479895592
,3720439432.301,53.1969680786133,0.503554224967957,-0.214374020695686
,3720439432.321,53.3457565307617,0.510726869106293,-0.209547653794289
,3720439432.341,53.4940910339355,0.5178342461586,-0.204779416322708
,3720439432.361,53.642578125,0.524835586547852,-0.200119599699974
,3720439432.381,53.7906036376953,0.531466484069824,-0.195822969079018
,3720439432.401,53.939697265625,0.538309156894684,-0.191331386566162
,3720439432.421,54.0886383056641,0.544431030750275,-0.187558203935623
,3720439432.441,54.2363624572754,0.550992429256439,-0.183326318860054
,3720439432.461,54.3849983215332,0.557277977466583,-0.179384648799896
;low temp = 299.989044189453 K;high temp = 300.003753662109 K;avg. temp = 299.996813964844 K;low field = 10000.1865234375 Oe;high field = 10000.1865234375 Oe;drift = 0.118269603699446 V/s;slope = -0.0157692804932594 V/mm;squid range = 1000;given center = 39.6060001694262 mm;calculated center = 41.9691047668457 mm;amp fixed = 2.19978499412537 V;amp free =1.4020699262619 V
,3720439434.45068,54.5256042480469,-0.362771213054657,-0.173417672514915
,3720439434.47068,54.3763618469238,-0.364467918872833,-0.177467823028564
,3720439434.49068,54.2260589599609,-0.366136491298676,-0.181506559252739
,3720439434.51068,54.0760612487793,-0.367997646331787,-0.185733079910278
,3720439434.53068,53.9263610839844,-0.370010226964951,-0.190106317400932
,3720439434.55068,53.7769660949707,-0.372332811355591,-0.194784760475159
,3720439434.57068,53.6275787353516,-0.374710917472839,-0.199518591165543
,3720439434.59068,53.4795455932617,-0.376872569322586,-0.204014629125595
,3720439434.61068,53.3312110900879,-0.379416763782501,-0.208897948265076
,3720439434.63068,53.1819686889648,-0.381833285093308,-0.213667914271355
,3720439434.65068,53.0336380004883,-0.384506106376648,-0.218679800629616
,3720439434.67068,52.8842430114746,-0.38735631108284,-0.223885864019394
,3720439434.69068,52.7366638183594,-0.390602260828018,-0.229459032416344
,3720439434.71068,52.5883331298828,-0.393532246351242,-0.234728083014488
,3720439434.73068,52.439998626709,-0.396719366312027,-0.240254327654839
,3720439434.75068,52.2912101745605,-0.400183647871017,-0.246064901351929
,3720439434.77068,52.142578125,-0.403648167848587,-0.251873224973679
,3720439434.79068,51.9943962097168,-0.407323658466339,-0.257885456085205
,3720439434.81068,51.8453025817871,-0.411119550466537,-0.264032453298569
,3720439434.83068,51.6966667175293,-0.415057301521301,-0.270314067602158
,3720439434.85068,51.5483360290527,-0.419028401374817,-0.276624232530594
,3720439434.87068,51.3998489379883,-0.42313614487648,-0.283073514699936
,3720439434.89068,51.2512092590332,-0.427562415599823,-0.289843738079071
,3720439434.91068,51.1019668579102,-0.431562930345535,-0.296197682619095
,3720439434.93068,50.9533348083496,-0.436157196760178,-0.30313578248024
,3720439434.95068,50.8040924072266,-0.440504908561707,-0.30983692407608
,3720439434.97068,50.6545448303223,-0.445278644561768,-0.31696891784668
,3720439434.99068,50.5059089660645,-0.449551492929459,-0.323585659265518
,3720439435.01068,50.3577308654785,-0.454396218061447,-0.330767035484314
,3720439435.03068,50.2087898254395,-0.458954721689224,-0.337674230337143
,3720439435.05068,50.0604553222656,-0.463993579149246,-0.34505221247673
,3720439435.07068,49.9119682312012,-0.468214184045792,-0.351614356040955
,3720439435.09068,49.763484954834,-0.473116904497147,-0.358858555555344
,3720439435.11068,49.6148490905762,-0.477543860673904,-0.365629404783249
,3720439435.13068,49.4663619995117,-0.482198894023895,-0.372625976800919
,3720439435.15068,49.3180313110352,-0.48623189330101,-0.378998041152954
,3720439435.17068,49.1695442199707,-0.490348756313324,-0.385456442832947
,3720439435.19068,49.0222702026367,-0.4943528175354,-0.391782909631729
,3720439435.21068,48.8737907409668,-0.498306035995483,-0.398077517747879
,3720439435.23068,48.7256050109863,-0.501747310161591,-0.403855592012405
,3720439435.25068,48.5763626098633,-0.505155146121979,-0.409616857767105
,3720439435.27068,48.4272689819336,-0.508402049541473,-0.415214866399765
,3720439435.29068,48.2781829833984,-0.510891616344452,-0.420055419206619
,3720439435.31068,48.129093170166,-0.513220191001892,-0.42473503947258
,3720439435.33068,47.9806060791016,-0.515048563480377,-0.428904950618744
,3720439435.35068,47.8316650390625,-0.516511499881744,-0.432716578245163
,3720439435.37068,47.6827278137207,-0.517084181308746,-0.435637891292572
,3720439435.39068,47.5333366394043,-0.517214834690094,-0.4381243288517
,3720439435.41068,47.3845443725586,-0.516600072383881,-0.43985590338707
,3720439435.43068,47.2351531982422,-0.515517055988312,-0.441128671169281
,3720439435.45068,47.0860595703125,-0.513584673404694,-0.441547393798828
,3720439435.47068,46.9375762939453,-0.510850787162781,-0.441154986619949
,3720439435.49068,46.7889404296875,-0.507440745830536,-0.440088838338852
,3720439435.51068,46.6398468017578,-0.503139555454254,-0.438138723373413
,3720439435.53068,46.4910583496094,-0.497639685869217,-0.434985160827637
,3720439435.55068,46.343334197998,-0.491419076919556,-0.43109405040741
,3720439435.57068,46.194393157959,-0.484031021595001,-0.426054686307907
,3720439435.59068,46.0456047058105,-0.475685507059097,-0.420055449008942
,3720439435.61068,45.8971176147461,-0.466094940900803,-0.412806421518326
,3720439435.63068,45.7490921020508,-0.455320358276367,-0.404366105794907
,3720439435.65068,45.6001510620117,-0.443223714828491,-0.394618153572082
,3720439435.67068,45.4513626098633,-0.430419594049454,-0.384160310029984
,3720439435.69068,45.303638458252,-0.416406810283661,-0.372477024793625
,3720439435.71068,45.1551513671875,-0.40135246515274,-0.359764218330383
,3720439435.73068,45.0063629150391,-0.384906888008118,-0.345664948225021
,3720439435.75068,44.8575782775879,-0.367492318153381,-0.330596596002579
,3720439435.77068,44.7096977233887,-0.348741769790649,-0.314178019762039
,3720439435.79068,44.5612106323242,-0.328607022762299,-0.296384811401367
,3720439435.81068,44.4133338928223,-0.307538568973541,-0.277648270130157
,3720439435.83068,44.2645454406738,-0.285221248865128,-0.257677227258682
,3720439435.85068,44.1162109375,-0.261723041534424,-0.236518144607544
,3720439435.87068,43.9675788879395,-0.236894935369492,-0.214033856987953
,3720439435.89068,43.8198471069336,-0.211167246103287,-0.190635800361633
,3720439435.91068,43.6707572937012,-0.184525772929192,-0.166345357894897
,3720439435.93068,43.5224227905273,-0.156853914260864,-0.141012623906136
,3720439435.95068,43.3737907409668,-0.128167152404785,-0.114669688045979
,3720439435.97068,43.2256050109863,-0.0988387241959572,-0.0876780450344086
,3720439435.99068,43.0762100219727,-0.0686581805348396,-0.0598533526062965
,3720439436.01068,42.9280319213867,-0.0379892401397228,-0.0315210707485676
,3720439436.03068,42.7803039550781,-0.00638708984479308,-0.00224848603829741
,3720439436.05068,42.6313629150391,0.0262365750968456,0.0280264858156443
,3720439436.07068,42.4830322265625,0.059481468051672,0.0589323118329048
,3720439436.09068,42.3348503112793,0.0931912735104561,0.090305395424366
,3720439436.11068,42.1863632202148,0.127256795763969,0.1220293790102
,3720439436.13068,42.0374221801758,0.162003114819527,0.154427006840706
,3720439436.15068,41.8887901306152,0.196557760238647,0.186637833714485
,3720439436.17068,41.7404556274414,0.231904357671738,0.21964530646801
,3720439436.19068,41.5915145874023,0.267041027545929,0.252433270215988
,3720439436.21068,41.4427299499512,0.303209781646729,0.286255806684494
,3720439436.23068,41.2940902709961,0.338350892066956,0.319052964448929
,3720439436.25068,41.1453018188477,0.374258697032928,0.352614492177963
,3720439436.27068,40.9968147277832,0.409386217594147,0.385400474071503
,3720439436.29068,40.848331451416,0.444636434316635,0.418309211730957
,3720439436.31068,40.6998481750488,0.479394376277924,0.450725674629211
,3720439436.33068,40.5506057739258,0.514309346675873,0.483287215232849
,3720439436.35068,40.4028778076172,0.548310041427612,0.514958322048187
,3720439436.37068,40.2537879943848,0.582045316696167,0.546342611312866
,3720439436.39068,40.1062126159668,0.614723861217499,0.576693952083588
,3720439436.41068,39.9574241638184,0.647170722484589,0.606794536113739
,3720439436.43068,39.8095474243164,0.678425371646881,0.635717272758484
,3720439436.45068,39.6607551574707,0.709074020385742,0.664019584655762
,3720439436.47068,39.5122718811035,0.738630354404449,0.691234469413757
,3720439436.49068,39.3643951416016,0.76690399646759,0.717176198959351
,3720439436.51068,39.2153015136719,0.794349074363709,0.742270171642303
,3720439436.53068,39.0665168762207,0.820228040218353,0.765802919864655
,3720439436.55068,38.9181823730469,0.844671368598938,0.787907123565674
,3720439436.57068,38.7701530456543,0.86778461933136,0.808686017990112
,3720439436.59068,38.6219711303711,0.889248430728912,0.82781308889389
,3720439436.61068,38.4745445251465,0.909534394741058,0.845774292945862
,3720439436.63068,38.3259086608887,0.927846431732178,0.861742436885834
,3720439436.65068,38.1780281066895,0.944262623786926,0.87582665681839
,3720439436.67068,38.0290908813477,0.958942234516144,0.888157606124878
,3720439436.69068,37.8798484802246,0.971510708332062,0.898372650146484
,3720439436.71068,37.7322731018066,0.982239902019501,0.906774699687958
,3720439436.73068,37.5833320617676,0.99101060628891,0.913196682929993
,3720439436.75068,37.4346961975098,0.997769355773926,0.917611598968506
,3720439436.77068,37.2857551574707,1.00242936611176,0.919922888278961
,3720439436.79068,37.1377258300781,1.0053825378418,0.920541763305664
,3720439436.81068,36.9887886047363,1.00576519966125,0.918575763702393
,3720439436.83068,36.8404541015625,1.00440359115601,0.914875030517578
,3720439436.85068,36.6915168762207,1.00150275230408,0.909625589847565
,3720439436.87068,36.5430297851562,0.996272683143616,0.902053952217102
,3720439436.89068,36.3946990966797,0.988747239112854,0.89218944311142
,3720439436.91068,36.2457580566406,0.979469656944275,0.880563199520111
,3720439436.93068,36.0971221923828,0.96800684928894,0.866756498813629
,3720439436.95068,35.9486351013184,0.954841554164887,0.851249635219574
,3720439436.97068,35.8001518249512,0.939685642719269,0.833752274513245
,3720439436.99068,35.6515159606934,0.923493385314941,0.81521612405777
,3720439437.01068,35.5028800964355,0.905180811882019,0.7945596575737
,3720439437.03068,35.3543930053711,0.885526120662689,0.772563457489014
,3720439437.05068,35.2062110900879,0.864506423473358,0.749207019805908
,3720439437.07068,35.0577278137207,0.842136859893799,0.724496006965637
,3720439437.09068,34.9090919494629,0.818971455097198,0.698986709117889
,3720439437.11068,34.7609100341797,0.794001579284668,0.671680092811585
,3720439437.13068,34.6127281188965,0.768126368522644,0.643468201160431
,3720439437.15068,34.4636344909668,0.741100132465363,0.614090859889984
,3720439437.17068,34.314998626709,0.713370740413666,0.58401757478714
,3720439437.19068,34.1663665771484,0.684571146965027,0.552874147891998
,3720439437.21068,34.0175743103027,0.655313611030579,0.521270275115967
,3720439437.23068,33.8686370849609,0.625506043434143,0.489114075899124
,3720439437.25068,33.7204551696777,0.595172107219696,0.456443428993225
,3720439437.27068,33.5716667175293,0.56455409526825,0.423479110002518
,3720439437.29068,33.4230308532715,0.533297538757324,0.389878690242767
,3720439437.31068,33.2745475769043,0.502007484436035,0.356247156858444
,3720439437.33068,33.1265144348145,0.470686197280884,0.322591483592987
,3720439437.35068,32.9775772094727,0.439239054918289,0.288795709609985
,3720439437.37068,32.8296966552734,0.407515823841095,0.254740506410599
,3720439437.39068,32.6807556152344,0.376245141029358,0.22112113237381
,3720439437.41068,32.5327262878418,0.344894170761108,0.18743585050106
,3720439437.43068,32.3833312988281,0.313812464475632,0.153998285531998
,3720439437.45068,32.2353019714355,0.282665252685547,0.120516762137413
,3720439437.47068,32.0868186950684,0.252491593360901,0.0880016312003136
,3720439437.49068,31.9375762939453,0.222436487674713,0.0555930770933628
,3720439437.51068,31.7895450592041,0.19318100810051,0.0240032523870468
,3720439437.53068,31.6409072875977,0.164160132408142,-0.00736153451725841
,3720439437.55068,31.4919700622559,0.136130884289742,-0.0377394147217274
,3720439437.57068,31.3431816101074,0.109219327569008,-0.0669972598552704
,3720439437.59068,31.1945457458496,0.0827053189277649,-0.0958551466464996
,3720439437.61068,31.0463638305664,0.0567780323326588,-0.124119155108929
,3720439437.63068,30.897575378418,0.0318187512457371,-0.151424720883369
,3720439437.65068,30.7492427825928,0.0080308960750699,-0.177551671862602
,3720439437.67068,30.6010589599609,-0.0151735562831163,-0.203092887997627
,3720439437.69068,30.4521217346191,-0.0374257601797581,-0.227693721652031
,3720439437.71068,30.3034839630127,-0.0584379732608795,-0.251049846410751
,3720439437.73068,30.1553020477295,-0.0784523263573647,-0.27340093255043
,3720439437.75068,30.0075759887695,-0.0969965234398842,-0.294274657964706
,3720439437.77068,29.8586349487305,-0.114758245646954,-0.314385056495666
,3720439437.79068,29.7093944549561,-0.131243750452995,-0.3332239985466
,3720439437.81068,29.5615158081055,-0.145839661359787,-0.350151836872101
,3720439437.83068,29.4122734069824,-0.160102039575577,-0.366767644882202
,3720439437.85068,29.2642440795898,-0.172660142183304,-0.38166007399559
,3720439437.87068,29.1154537200928,-0.184745818376541,-0.396092057228088
,3720439437.89068,28.9671211242676,-0.194883286952972,-0.408568650484085
,3720439437.91068,28.8187885284424,-0.204391419887543,-0.420415878295898
,3720439437.93068,28.669849395752,-0.21258807182312,-0.430961191654205
,3720439437.95068,28.5219707489014,-0.219845905900002,-0.440550953149796
,3720439437.97068,28.3730297088623,-0.225479081273079,-0.448532819747925
,3720439437.99068,28.2250003814697,-0.230575442314148,-0.455963492393494
,3720439438.01068,28.0760593414307,-0.234046697616577,-0.461783438920975
,3720439438.03068,27.9277267456055,-0.237394601106644,-0.467470467090607
,3720439438.05068,27.7784843444824,-0.238636314868927,-0.471065610647202
,3720439438.07068,27.6299991607666,-0.239882379770279,-0.47465318441391
,3720439438.09068,27.4815158843994,-0.239682480692863,-0.476794749498367
,3720439438.11068,27.332727432251,-0.238790556788445,-0.478249132633209
,3720439438.13068,27.1843948364258,-0.237174689769745,-0.478972345590591
,3720439438.15068,27.0359077453613,-0.234559789299965,-0.478698998689652
,3720439438.17068,26.8871212005615,-0.231584310531616,-0.478069752454758
,3720439438.19068,26.7380294799805,-0.227687418460846,-0.47652393579483
,3720439438.21068,26.5898494720459,-0.223361924290657,-0.474535137414932
,3720439438.23068,26.4409084320068,-0.218300104141235,-0.471822023391724
,3720439438.25068,26.2925758361816,-0.212948769330978,-0.46880978345871
,3720439438.27068,26.1442432403564,-0.207193344831467,-0.465393453836441
,3720439438.29068,25.9959087371826,-0.20041199028492,-0.460951209068298
,3720439438.31068,25.8472728729248,-0.193517908453941,-0.456401020288467
,3720439438.33068,25.6984844207764,-0.186246886849403,-0.451476275920868
,3720439438.35068,25.5506057739258,-0.178835451602936,-0.446396797895431
,3720439438.37068,25.4016666412354,-0.171300634741783,-0.441210627555847
,3720439438.39068,25.2531814575195,-0.163536921143532,-0.435788422822952
,3720439438.41068,25.1039409637451,-0.155613213777542,-0.430218130350113
,3720439438.43068,24.9560604095459,-0.147281050682068,-0.424217939376831
,3720439438.45068,24.8074245452881,-0.138914555311203,-0.418195337057114
,3720439439.36884,24.6060009002686,,,-0.225555017590523,-0.391066789627075
,3720439439.38884,24.7560005187988,,,-0.230262517929077,-0.397263824939728
,3720439439.40884,24.9060001373291,,,-0.235051825642586,-0.403317928314209
,3720439439.42884,25.0559997558594,,,-0.239918038249016,-0.409199893474579
,3720439439.44884,25.2059993743896,,,-0.244855672121048,-0.4148790538311
,3720439439.46884,25.3560009002686,,,-0.249858245253563,-0.420322597026825
,3720439439.48884,25.5060005187988,,,-0.25491851568222,-0.425496309995651
,3720439439.50884,25.6560001373291,,,-0.26002836227417,-0.43036425113678
,3720439439.52884,25.8059997558594,,,-0.265178382396698,-0.43488872051239
,3720439439.54884,25.9559993743896,,,-0.270358473062515,-0.439030796289444
,3720439439.56884,26.1060009002686,,,-0.275557100772858,-0.442749977111816
,3720439439.58884,26.2560005187988,,,-0.28076171875,-0.446004748344421
,3720439439.60884,26.4060001373291,,,-0.285958617925644,-0.448752641677856
,3720439439.62884,26.5559997558594,,,-0.291132599115372,-0.450950115919113
,3720439439.64884,26.7059993743896,,,-0.296267360448837,-0.452553361654282
,3720439439.66884,26.8560009002686,,,-0.30134516954422,-0.453518033027649
,3720439439.68884,27.0060005187988,,,-0.306346744298935,-0.453799784183502
,3720439439.70884,27.1560001373291,,,-0.311251699924469,-0.453354567289352
,3720439439.72884,27.3059997558594,,,-0.316037893295288,-0.452138781547546
,3720439439.74884,27.4559993743896,,,-0.320681989192963,-0.450109750032425
,3720439439.76884,27.6060009002686,,,-0.325159192085266,-0.447225868701935
,3720439439.78884,27.7560005187988,,,-0.329443156719208,-0.443447262048721
,3720439439.80884,27.9060001373291,,,-0.333506375551224,-0.438735693693161
,3720439439.82884,28.0559997558594,,,-0.337319880723953,-0.433055311441422
,3720439439.84884,28.2059993743896,,,-0.34085351228714,-0.426372647285461
,3720439439.86884,28.3560009002686,,,-0.344076097011566,-0.418657034635544
,3720439439.88884,28.5060005187988,,,-0.346955150365829,-0.409881263971329
,3720439439.90884,28.6560001373291,,,-0.349457561969757,-0.400021106004715
,3720439439.92884,28.8059997558594,,,-0.351549237966537,-0.389056444168091
,3720439439.94884,28.9560012817383,,,-0.353195607662201,-0.376970767974854
,3720439439.96884,29.1060009002686,,,-0.354361653327942,-0.363751620054245
,3720439439.98884,29.2560005187988,,,-0.355012118816376,-0.349391281604767
,3720439440.00884,29.4060001373291,,,-0.35511177778244,-0.333885759115219
,3720439440.02884,29.5559997558594,,,-0.354625642299652,-0.317236334085464
,3720439440.04884,29.7060012817383,,,-0.353519171476364,-0.299448251724243
,3720439440.06884,29.8560009002686,,,-0.351758569478989,-0.280531227588654
,3720439440.08884,30.0060005187988,,,-0.349311143159866,-0.260500401258469
,3720439440.10884,30.1560001373291,,,-0.346145331859589,-0.239374622702599
,3720439440.12884,30.3059997558594,,,-0.342231154441833,-0.217177197337151
,3720439440.14884,30.4560012817383,,,-0.337540507316589,-0.193936675786972
,3720439440.16884,30.6060009002686,,,-0.332047194242477,-0.169684693217278
,3720439440.18884,30.7560005187988,,,-0.325727581977844,-0.144458219408989
,3720439440.20884,30.9060001373291,,,-0.318560361862183,-0.118297323584557
,3720439440.22884,31.0559997558594,,,-0.310526967048645,-0.0912458375096321
,3720439440.24884,31.2060012817383,,,-0.301612108945847,-0.0633523091673851
,3720439440.26884,31.3560009002686,,,-0.291803240776062,-0.0346674211323261
,3720439440.28884,31.5060005187988,,,-0.281091541051865,-0.00524664204567671
,3720439440.30884,31.6560001373291,,,-0.269471257925034,0.0248524472117424
,3720439440.32884,31.8059997558594,,,-0.25694015622139,0.0555692426860332
,3720439440.34884,31.9560012817383,,,-0.243500038981438,0.0868390500545502
,3720439440.36884,32.1059989929199,,,-0.229155853390694,0.118595577776432
,3720439440.38884,32.2560005187988,,,-0.213916376233101,0.150769472122192
,3720439440.40884,32.4060020446777,,,-0.197793573141098,0.183289706707001
,3720439440.42884,32.5559997558594,,,-0.180804282426834,0.216080322861671
,3720439440.44884,32.7060012817383,,,-0.162967622280121,0.249065533280373
,3720439440.46884,32.8559989929199,,,-0.144306614995003,0.282166570425034
,3720439440.48884,33.0060005187988,,,-0.12484759837389,0.315302550792694
,3720439440.50884,33.1560020446777,,,-0.104619696736336,0.348391443490982
,3720439440.52884,33.3059997558594,,,-0.0836567059159279,0.38134691119194
,3720439440.54884,33.4560012817383,,,-0.0619939081370831,0.414083421230316
,3720439440.56884,33.6059989929199,,,-0.0396700017154217,0.446513086557388
,3720439440.58884,33.7560005187988,,,-0.0167264454066753,0.47854670882225
,3720439440.60884,33.9060020446777,,,0.00679325917735696,0.51009476184845
,3720439440.62884,34.0559997558594,,,0.0308412984013557,0.541064321994782
,3720439440.64884,34.2060012817383,,,0.0553692355751991,0.571364521980286
,3720439440.66884,34.3559989929199,,,0.0803257450461388,0.60090309381485
,3720439440.68884,34.5060005187988,,,0.105657331645489,0.629588127136231
,3720439440.70884,34.6560020446777,,,0.131309047341347,0.657328605651855
,3720439440.72884,34.8059997558594,,,0.157222017645836,0.684032440185547
,3720439440.74884,34.9560012817383,,,0.183337390422821,0.709610819816589
,3720439440.76884,35.1059989929199,,,0.20959384739399,0.733976125717163
,3720439440.78884,35.2560005187988,,,0.235928371548653,0.75704300403595
,3720439440.80884,35.4060020446777,,,0.262276947498322,0.778729498386383
,3720439440.82884,35.5559997558594,,,0.288572043180466,0.798955261707306
,3720439440.84884,35.7060012817383,,,0.314746648073196,0.817645728588104
,3720439440.86884,35.8559989929199,,,0.340731859207153,0.834730088710785
,3720439440.88884,36.0060005187988,,,0.366457521915436,0.850142657756805
,3720439440.90884,36.1560020446777,,,0.391853094100952,0.863823652267456
,3720439440.92884,36.3059997558594,,,0.416845291852951,0.875718176364899
,3720439440.94884,36.4560012817383,,,0.441362082958221,0.885779082775116
,3720439440.96884,36.6059989929199,,,0.465330392122269,0.893965661525726
,3720439440.98884,36.7560005187988,,,0.488676965236664,0.900244534015656
,3720439441.00884,36.9060020446777,,,0.511329174041748,0.90459007024765
,3720439441.02884,37.0559997558594,,,0.533213198184967,0.906984090805054
,3720439441.04884,37.2060012817383,,,0.55425763130188,0.907416880130768
,3720439441.06884,37.3559989929199,,,0.574391543865204,0.905886590480804
,3720439441.08884,37.5060005187988,,,0.59354567527771,0.90239953994751
,3720439441.10884,37.6560020446777,,,0.611652553081512,0.896970212459564
,3720439441.12884,37.8059997558594,,,0.62864762544632,0.889620721340179
,3720439441.14884,37.9560012817383,,,0.644467651844025,0.880381405353546
,3720439441.16884,38.1059989929199,,,0.659053981304169,0.869289636611938
,3720439441.18884,38.2560005187988,,,0.6723513007164,0.856389939785004
,3720439441.20884,38.4060020446777,,,0.684308171272278,0.841733753681183
,3720439441.22884,38.5559997558594,,,0.694878160953522,0.825378060340881
,3720439441.24884,38.7060012817383,,,0.704018712043762,0.807387113571167
,3720439441.26884,38.8559989929199,,,0.711693465709686,0.787829041481018
,3720439441.28884,39.0060005187988,,,0.717871367931366,0.766777217388153
,3720439441.30884,39.1560020446777,,,0.722527146339416,0.744309067726135
,3720439441.32884,39.3059997558594,,,0.725641846656799,0.720505118370056
,3720439441.34884,39.4560012817383,,,0.727202355861664,0.695450782775879
,3720439441.36884,39.6059989929199,,,0.727202355861664,0.669232070446014
,3720439441.38884,39.7560005187988,,,0.725641787052154,0.641937851905823
,3720439441.40884,39.9060020446777,,,0.722527205944061,0.61365818977356
,3720439441.42884,40.0559997558594,,,0.717871308326721,0.584483802318573
,3720439441.44884,40.2060012817383,,,0.711693406105042,0.554507911205292
,3720439441.46884,40.3559989929199,,,0.704018592834473,0.523822069168091
,3720439441.48884,40.5060005187988,,,0.694878041744232,0.492518156766891
,3720439441.50884,40.6560020446777,,,0.684308350086212,0.460687756538391
,3720439441.52884,40.8059997558594,,,0.672351121902466,0.428420782089233
,3720439441.54884,40.9560012817383,,,0.659053862094879,0.395808577537537
,3720439441.56884,41.1059989929199,,,0.64446747303009,0.36293888092041
,3720439441.58884,41.2560005187988,,,0.628647446632385,0.329898744821548
,3720439441.60884,41.4060020446777,,,0.611652851104736,0.296773582696915
,3720439441.62884,41.5559997558594,,,0.593545496463776,0.263646215200424
,3720439441.64884,41.7060012817383,,,0.57439136505127,0.230600103735924
,3720439441.66884,41.8559989929199,,,0.554257392883301,0.197714149951935
,3720439441.68884,42.0060005187988,,,0.533213019371033,0.16506589949131
,3720439441.70884,42.1560020446777,,,0.511328995227814,0.132730692625046
,3720439441.72884,42.3059997558594,,,0.488676756620407,0.100780688226223
,3720439441.74884,42.4560012817383,,,0.465330183506012,0.069287970662117
,3720439441.76884,42.6059989929199,,,0.441361844539642,0.0383195877075195
,3720439441.78884,42.7560005187988,,,0.416845053434372,0.00794069934636354
,3720439441.80884,42.9060020446777,,,0.391852855682373,-0.0217863991856575
,3720439441.82884,43.0559997558594,,,0.366457283496857,-0.0508031249046326
,3720439441.84884,43.2060012817383,,,0.340731620788574,-0.0790518373250961
,3720439441.86884,43.3560028076172,,,0.314746409654617,-0.106480397284031
,3720439441.88884,43.5060005187988,,,0.288571774959564,-0.133039370179176
,3720439441.90884,43.6560020446777,,,0.26227667927742,-0.158682942390442
,3720439441.92884,43.8059997558594,,,0.235928773880005,-0.183369025588036
,3720439441.94884,43.9560012817383,,,0.209593594074249,-0.207060068845749
,3720439441.96884,44.1060028076172,,,0.183337137103081,-0.229720816016197
,3720439441.98884,44.2560005187988,,,0.157221764326096,-0.251322001218796
,3720439442.00884,44.4060020446777,,,0.131308808922768,-0.27183809876442
[...]
,3720446285.52937,34.4545440673828,-0.443837434053421,0.782582402229309
,3720446285.54937,34.306209564209,-0.461162447929382,0.765255868434906
,3720446285.56937,34.1572723388672,-0.479724556207657,0.746692180633545
,3720446285.58937,34.0086364746094,-0.499778509140015,0.726636707782745
,3720446285.60937,33.8606071472168,-0.521159887313843,0.705253779888153
,3720446285.62937,33.712272644043,-0.543778836727142,0.682633280754089
,3720446285.64937,33.5634841918945,-0.567815542221069,0.658595025539398
,3720446285.66937,33.4146957397461,-0.59290874004364,0.633500277996063
,3720446285.68937,33.2659072875977,-0.618986666202545,0.607420802116394
,3720446285.70937,33.1169700622559,-0.646294951438904,0.580110967159271
,3720446285.72937,32.9687881469727,-0.67393034696579,0.552474021911621
,3720446285.74937,32.8203010559082,-0.702759206295013,0.523643612861633
,3720446285.76937,32.6719703674316,-0.732369422912598,0.494031846523285
,3720446285.78937,32.5236358642578,-0.762123107910156,0.464276611804962
,3720446285.80937,32.374698638916,-0.792388558387756,0.434009611606598
,3720446285.82937,32.2266693115234,-0.8231121301651,0.403284519910812
,3720446285.84937,32.0778770446777,-0.854229152202606,0.372165948152542
,3720446285.86937,31.9292430877686,-0.885698616504669,0.340694934129715
,3720446285.88937,31.7809085845947,-0.916991829872131,0.309400171041489
,3720446285.90937,31.6318187713623,-0.94826865196228,0.278121799230576
,3720446285.92937,31.4839401245117,-0.979384005069733,0.247004896402359
,3720446285.94937,31.3353023529053,-1.01020264625549,0.216184705495834
,3720446285.96937,31.1871223449707,-1.04136216640472,0.185023650527
,3720446285.98937,31.037878036499,-1.07251834869385,0.153865918517113
,3720446286.00937,30.8893947601318,-1.10302948951721,0.123353227972984
,3720446286.02937,30.7409076690674,-1.1334456205368,0.0929355472326279
,3720446286.04937,30.5922737121582,-1.16340219974518,0.0629774183034897
,3720446286.06937,30.4434833526611,-1.19287872314453,0.0334993489086628
,3720446286.08937,30.2956047058105,-1.22148752212524,0.00488900952041149
,3720446286.10937,30.1465167999268,-1.24976444244385,-0.0233894623816013
,3720446286.12937,29.9983329772949,-1.27778303623199,-0.0514095984399319
,3720446286.14937,29.8495464324951,-1.30464339256287,-0.0782715082168579
,3720446286.16937,29.7013645172119,-1.33074080944061,-0.104370467364788
,3720446286.18937,29.5527267456055,-1.35598814487457,-0.129619345068932
,3720446286.20937,29.4040908813477,-1.38018119335175,-0.153813943266869
,3720446286.22937,29.2556056976318,-1.4034515619278,-0.177085861563683
,3720446286.24937,29.1072731018066,-1.4262889623642,-0.199924811720848
,3720446286.26937,28.9586353302002,-1.44783973693848,-0.221477121114731
,3720446286.28937,28.8092422485352,-1.46862733364105,-0.242266282439232
,3720446286.30937,28.6616668701172,-1.48801350593567,-0.261653989553452
,3720446286.32937,28.5121212005615,-1.50671136379242,-0.280353397130966
,3720446286.34937,28.3640918731689,-1.52405858039856,-0.29770216345787
,3720446286.36937,28.2157573699951,-1.54020440578461,-0.313849538564682
,3720446286.38937,28.0674247741699,-1.55544555187225,-0.329092234373093
,3720446286.40937,27.9180297851562,-1.56954336166382,-0.343191593885422
,3720446286.42937,27.7693939208984,-1.58255100250244,-0.356200784444809
,3720446286.44937,27.6213645935059,-1.59410679340363,-0.367758095264435
,3720446286.46937,27.4725761413574,-1.6050945520401,-0.378747403621674
,3720446286.48937,27.3242435455322,-1.61410045623779,-0.387754857540131
,3720446286.50937,27.1760597229004,-1.62261772155762,-0.396273672580719
,3720446286.52937,27.0277271270752,-1.62992537021637,-0.403582870960236
,3720446286.54937,26.8786354064941,-1.63678550720215,-0.410444557666779
,3720446286.56937,26.7306060791016,-1.64166164398193,-0.415322244167328
,3720446286.58937,26.5819702148438,-1.64638006687164,-0.420042216777802
,3720446286.60937,26.4333324432373,-1.64992642402649,-0.423590123653412
,3720446286.62937,26.2843952178955,-1.65285861492157,-0.426523864269257
,3720446286.64937,26.1359081268311,-1.65457630157471,-0.428243070840836
,3720446286.66937,25.9871215820313,-1.65560340881348,-0.429271727800369
,3720446286.68937,25.8384838104248,-1.65599882602692,-0.429668694734573
,3720446286.70937,25.6901512145996,-1.65548396110535,-0.429155379533768
,3720446286.72937,25.5416679382324,-1.65436363220215,-0.428036600351334
,3720446286.74937,25.393030166626,-1.65269041061401,-0.426364928483963
,3720446286.76937,25.2445449829102,-1.65048599243164,-0.424162060022354
,3720446286.78937,25.0959091186523,-1.64779198169708,-0.42146959900856
,3720446286.80937,24.9465160369873,-1.64430022239685,-0.417979389429092
,3720446286.82937,24.7978782653809,-1.64051353931427,-0.414194256067276
,3720446286.84937,24.6504535675049,-1.63667047023773,-0.41035270690918
,3720446286.86937,24.5016670227051,-1.63183283805847,-0.405516624450684
,3720446286.88937,24.3519706726074,-1.62722504138947,-0.400910407304764
,3720446286.90937,24.2045459747314,-1.62215948104858,-0.395846366882324
,3720446286.92937,24.055757522583,-1.61692893505096,-0.390617370605469
,3720446286.94937,23.9072723388672,-1.61100387573242,-0.38469386100769
,3720446287.56241,23.699686050415,,,-0.188307330012321,-0.386512458324432
,3720446287.58241,23.8496856689453,,,-0.192237675189972,-0.391793608665466
,3720446287.60241,23.9996852874756,,,-0.196236327290535,-0.396849721670151
,3720446287.62241,24.1496849060059,,,-0.200299188494682,-0.401648283004761
,3720446287.64241,24.2996864318848,,,-0.204421684145927,-0.406155526638031
,3720446287.66241,24.449686050415,,,-0.208598405122757,-0.41033598780632
,3720446287.68241,24.5996856689453,,,-0.212823286652565,-0.414152950048447
,3720446287.70241,24.7496852874756,,,-0.217089548707008,-0.417568564414978
,3720446287.72241,24.8996849060059,,,-0.221389383077621,-0.420543640851974
,3720446287.74241,25.0496864318848,,,-0.225714296102524,-0.423038363456726
,3720446287.76241,25.199686050415,,,-0.230054676532745,-0.425011992454529
,3720446287.78241,25.3496856689453,,,-0.23440009355545,-0.426423341035843
,3720446287.80241,25.4996852874756,,,-0.238739058375359,-0.427231013774872
,3720446287.82241,25.6496849060059,,,-0.243058875203133,-0.427393525838852
,3720446287.84241,25.7996864318848,,,-0.247345939278603,-0.426869690418243
,3720446287.86241,25.949686050415,,,-0.251585453748703,-0.425618797540665
,3720446287.88241,26.0996856689453,,,-0.255761355161667,-0.423601120710373
,3720446287.90241,26.2496852874756,,,-0.259856551885605,-0.420777946710587
,3720446287.92241,26.3996849060059,,,-0.263852626085281,-0.417112201452255
,3720446287.94241,26.5496864318848,,,-0.26773002743721,-0.412568420171738
,3720446287.96241,26.699686050415,,,-0.271468102931976,-0.407113313674927
,3720446287.98241,26.8496856689453,,,-0.275044828653336,-0.400716066360474
,3720446288.00241,26.9996852874756,,,-0.278437286615372,-0.393348425626755
,3720446288.02241,27.1496849060059,,,-0.281621187925339,-0.384985327720642
,3720446288.04241,27.2996864318848,,,-0.284571498632431,-0.375604778528214
,3720446288.06241,27.449686050415,,,-0.287262052297592,-0.365188151597977
,3720446288.08241,27.5996856689453,,,-0.289665818214417,-0.353720933198929
,3720446288.10241,27.7496852874756,,,-0.291755110025406,-0.341191947460175
,3720446288.12241,27.8996849060059,,,-0.293501496315002,-0.327594578266144
,3720446288.14241,28.0496864318848,,,-0.29487606883049,-0.312925964593887
,3720446288.16241,28.199686050415,,,-0.295849621295929,-0.297187328338623
,3720446288.18241,28.3496856689453,,,-0.296392679214478,-0.280384808778763
,3720446288.20241,28.4996852874756,,,-0.296475887298584,-0.262528002262115
,3720446288.22241,28.6496868133545,,,-0.296070009469986,-0.243631675839424
,3720446288.24241,28.7996864318848,,,-0.295146197080612,-0.223714113235474
,3720446288.26241,28.949686050415,,,-0.293676257133484,-0.202797785401344
,3720446288.28241,29.0996856689453,,,-0.291632890701294,-0.180909961462021
,3720446288.30241,29.2496852874756,,,-0.288989692926407,-0.158081158995628
,3720446288.32241,29.3996868133545,,,-0.285721689462662,-0.134345665574074
,3720446288.34241,29.5496864318848,,,-0.281805425882339,-0.109742388129234
,3720446288.36241,29.699686050415,,,-0.277218997478485,-0.0843125730752945
,3720446288.38241,29.8496856689453,,,-0.271942675113678,-0.0581021644175053
,3720446288.40241,29.9996852874756,,,-0.265958666801453,-0.0311593916267157
,3720446288.42241,30.1496868133545,,,-0.259251475334167,-0.00353558291681111
,3720446288.44241,30.2996864318848,,,-0.251808375120163,0.0247139148414135
,3720446288.46241,30.449686050415,,,-0.243618816137314,0.0535323247313499
,3720446288.48241,30.5996856689453,,,-0.234675496816635,0.0828587263822556
,3720446288.50241,30.7496852874756,,,-0.2249735891819,0.112630717456341
,3720446288.52241,30.8996868133545,,,-0.214511215686798,0.142783433198929
,3720446288.54241,31.0496864318848,,,-0.20328988134861,0.173248529434204
,3720446288.56241,31.199686050415,,,-0.191313594579697,0.203956931829453
,3720446288.58241,31.3496856689453,,,-0.178589954972267,0.234835878014565
,3720446288.60241,31.4996852874756,,,-0.165129169821739,0.265811771154404
,3720446288.62241,31.6496868133545,,,-0.150944426655769,0.296808987855911
,3720446288.64241,31.7996864318848,,,-0.136052384972572,0.327749043703079
,3720446288.66241,31.949686050415,,,-0.120472066104412,0.358552843332291
,3720446288.68241,32.0996856689453,,,-0.104225501418114,0.389139354228973
,3720446288.70241,32.2496871948242,,,-0.0873369723558426,0.419426918029785
,3720446288.72241,32.3996849060059,,,-0.0698347017168999,0.449330389499664
,3720446288.74241,32.5496864318848,,,-0.0517481677234173,0.478765845298767
,3720446288.76241,32.6996841430664,,,-0.0331096611917019,0.50764787197113
,3720446288.78241,32.8496856689453,,,-0.0139538012444973,0.535890519618988
,3720446288.80241,32.9996871948242,,,0.00568309240043163,0.563408315181732
,3720446288.82241,33.1496849060059,,,0.0257610995322466,0.590113699436188
,3720446288.84241,33.2996864318848,,,0.0462397783994675,0.615921854972839
,3720446288.86241,33.4496879577637,,,0.0670762807130814,0.640747964382172
,3720446288.88241,33.5996856689453,,,0.0882259383797646,0.664508640766144
,3720446288.90241,33.7496871948242,,,0.109642878174782,0.687122702598572
,3720446288.92241,33.8996849060059,,,0.131277933716774,0.708509564399719
,3720446288.94241,34.0496864318848,,,0.153081983327866,0.728592991828918
,3720446288.96241,34.1996879577637,,,0.175003826618195,0.747299551963806
,3720446288.98241,34.3496856689453,,,0.196990847587585,0.764559388160706
,3720446289.00241,34.4996871948242,,,0.218989610671997,0.780307471752167
,3720446289.02241,34.6496849060059,,,0.24094370007515,0.794482231140137
,3720446289.04241,34.7996864318848,,,0.262797236442566,0.807028651237488
,3720446289.06241,34.9496879577637,,,0.284492611885071,0.817897081375122
,3720446289.08241,35.0996856689453,,,0.305971264839172,0.827043831348419
,3720446289.10241,35.2496871948242,,,0.327174365520477,0.834432125091553
,3720446289.12241,35.3996849060059,,,0.348040640354156,0.840031445026398
,3720446289.14241,35.5496864318848,,,0.368510037660599,0.843818962574005
,3720446289.16241,35.6996879577637,,,0.388521492481232,0.845779120922089
,3720446289.18241,35.8496856689453,,,0.408013820648193,0.845903754234314
,3720446289.20241,35.9996871948242,,,0.426926463842392,0.844192326068878
,3720446289.22241,36.1496849060059,,,0.44519767165184,0.840651988983154
,3720446289.24241,36.2996864318848,,,0.46276792883873,0.835297286510468
,3720446289.26241,36.4496879577637,,,0.479577988386154,0.828150272369385
,3720446289.28241,36.5996856689453,,,0.495570003986359,0.819240093231201
,3720446289.30241,36.7496871948242,,,0.510687708854675,0.808602929115295
,3720446289.32241,36.8996849060059,,,0.524877071380615,0.796281099319458
,3720446289.34241,37.0496864318848,,,0.538085401058197,0.782324135303497
,3720446289.36241,37.1996879577637,,,0.55026376247406,0.766786396503448
,3720446289.38241,37.3496856689453,,,0.561365783214569,0.74972802400589
,3720446289.40241,37.4996871948242,,,0.571348786354065,0.731213808059692
,3720446289.42241,37.6496849060059,,,0.580173790454865,0.711312413215637
,3720446289.44241,37.7996864318848,,,0.587805330753326,0.690097987651825
,3720446289.46241,37.9496879577637,,,0.594213128089905,0.66764634847641
,3720446289.48241,38.0996856689453,,,0.599371135234833,0.644036591053009
,3720446289.50241,38.2496871948242,,,0.603258311748505,0.619350135326386
,3720446289.52241,38.3996849060059,,,0.60585880279541,0.593669652938843
,3720446289.54241,38.5496864318848,,,0.607161700725555,0.567080974578857
,3720446289.56241,38.6996879577637,,,0.607161700725555,0.539669036865234
,3720446289.58241,38.8496856689453,,,0.60585880279541,0.51151978969574
,3720446289.60241,38.9996871948242,,,0.603258371353149,0.482719451189041
,3720446289.62241,39.1496849060059,,,0.599371075630188,0.453353315591812
,3720446289.64241,39.2996864318848,,,0.59421306848526,0.423508375883102
,3720446289.66241,39.4496879577637,,,0.587805330753326,0.393268644809723
,3720446289.68241,39.5996856689453,,,0.58017373085022,0.36271795630455
,3720446289.70241,39.7496871948242,,,0.571348965167999,0.331938862800598
,3720446289.72241,39.8996849060059,,,0.561365783214569,0.301011830568314
,3720446289.74241,40.0496864318848,,,0.550263702869415,0.270018070936203
,3720446289.76241,40.1996879577637,,,0.538085341453552,0.239034861326218
,3720446289.78241,40.3496856689453,,,0.52487701177597,0.208138361573219
,3720446289.80241,40.4996871948242,,,0.510688006877899,0.177402883768082
,3720446289.82241,40.6496849060059,,,0.495569944381714,0.146899923682213
,3720446289.84241,40.7996864318848,,,0.479577898979187,0.116701140999794
,3720446289.86241,40.9496879577637,,,0.462767839431763,0.0868736654520035
,3720446289.88241,41.0996856689453,,,0.445197612047195,0.0574830658733845
,3720446289.90241,41.2496871948242,,,0.426926374435425,0.0285924524068832
,3720446289.92241,41.3996849060059,,,0.408013731241226,0.000261662615230307
,3720446289.94241,41.5496864318848,,,0.388521373271942,-0.027450006455183
,3720446289.96241,41.6996879577637,,,0.368509948253632,-0.0544882342219353
,3720446289.98241,41.8496856689453,,,0.348040550947189,-0.08080093562603
,3720446290.00241,41.9996871948242,,,0.327174246311188,-0.106339119374752
,3720446290.02241,42.1496849060059,,,0.305971175432205,-0.131057664752007
,3720446290.04241,42.2996864318848,,,0.284492492675781,-0.15491296350956
,3720446290.06241,42.4496879577637,,,0.262797117233276,-0.177866861224174
,3720446290.08241,42.5996856689453,,,0.240943595767021,-0.199884250760078
,3720446290.10241,42.7496871948242,,,0.218989506363869,-0.220933839678764
,3720446290.12241,42.8996849060059,,,0.196990743279457,-0.240988805890083
,3720446290.14241,43.0496864318848,,,0.175003722310066,-0.260024875402451
,3720446290.16241,43.1996879577637,,,0.153081879019737,-0.278023451566696
,3720446290.18241,43.3496856689453,,,0.131277829408646,-0.29496967792511
,3720446290.20241,43.4996871948242,,,0.109642773866653,-0.310852915048599
,3720446290.22241,43.6496849060059,,,0.0882263779640198,-0.325666904449463
,3720446290.24241,43.7996864318848,,,0.0670761838555336,-0.33940988779068
,3720446290.26241,43.9496879577637,,,0.0462396815419197,-0.352083384990692
,3720446290.28241,44.0996856689453,,,0.0257610026746988,-0.363694101572037
,3720446290.30241,44.2496871948242,,,0.00568299740552902,-0.374252378940582
,3720446290.32241,44.3996849060059,,,-0.0139534035697579,-0.383772492408752
,3720446290.34241,44.5496864318848,,,-0.033109750598669,-0.392272651195526
,3720446290.36241,44.6996879577637,,,-0.0517482571303844,-0.399773895740509
,3720446290.38241,44.8496856689453,,,-0.069834791123867,-0.406301200389862
,3720446290.40241,44.9996871948242,,,-0.0873370543122292,-0.411882340908051
,3720446290.42241,45.1496849060059,,,-0.104225158691406,-0.416547864675522
,3720446290.44241,45.2996864318848,,,-0.120472148060799,-0.420330822467804
,3720446290.46241,45.4496879577637,,,-0.136052459478378,-0.423266142606735
,3720446290.48241,45.5996856689453,,,-0.150944486260414,-0.425390869379044
,3720446290.50241,45.7496871948242,,,-0.165129065513611,-0.426743477582932
,3720446290.52241,45.8996849060059,,,-0.178589850664139,-0.427363604307175
,3720446290.54241,46.0496864318848,,,-0.191313803195953,-0.427291810512543
,3720446290.56241,46.1996879577637,,,-0.203289940953255,-0.426569253206253
,3720446290.58241,46.3496856689453,,,-0.214511275291443,-0.425237387418747
,3720446290.60241,46.4996871948242,,,-0.224973514676094,-0.423337638378143
,3720446290.62241,46.6496849060059,,,-0.234675422310829,-0.420911252498627
,3720446290.64241,46.7996864318848,,,-0.243618965148926,-0.417998909950256
,3720446290.66241,46.9496879577637,,,-0.251808404922485,-0.414640784263611
,3720446290.68241,47.0996856689453,,,-0.259251534938812,-0.410876035690308
,3720446290.70241,47.2496871948242,,,-0.265958607196808,-0.406742721796036
,3720446290.72241,47.3996849060059,,,-0.271942615509033,-0.402277767658234
,3720446290.74241,47.5496864318848,,,-0.277219086885452,-0.39751660823822
,3720446290.76241,47.6996879577637,,,-0.281805455684662,-0.392493546009064
,3720446290.78241,47.8496856689453,,,-0.285721719264984,-0.387241095304489
,3720446290.80241,47.9996871948242,,,-0.288989692926407,-0.381790190935135
,3720446290.82241,48.1496849060059,,,-0.291632860898972,-0.376170217990875
,3720446290.84241,48.2996864318848,,,-0.293676286935806,-0.370408624410629
,3720446290.86241,48.4496879577637,,,-0.295146197080612,-0.364531725645065
,3720446290.88241,48.5996856689453,,,-0.296070009469986,-0.358563661575317
,3720446290.90241,48.7496871948242,,,-0.296475887298584,-0.352527052164078
,3720446290.92241,48.8996849060059,,,-0.296392679214478,-0.34644290804863
,3720446290.94241,49.0496864318848,,,-0.295849591493607,-0.340330481529236
,3720446290.96241,49.1996879577637,,,-0.29487606883049,-0.334207892417908
,3720446290.98241,49.3496856689453,,,-0.29350146651268,-0.328091323375702
,3720446291.00241,49.4996871948242,,,-0.291755110025406,-0.321995675563812
,3720446291.02241,49.6496849060059,,,-0.289665848016739,-0.315934419631958
,3720446291.04241,49.7996864318848,,,-0.287262082099915,-0.309919774532318
,3720446291.06241,49.9496879577637,,,-0.284571468830109,-0.303962469100952
,3720446291.08241,50.0996856689453,,,-0.281621187925339,-0.29807260632515
,3720446291.10241,50.2496871948242,,,-0.278437256813049,-0.292258620262146
,3720446291.12241,50.3996849060059,,,-0.275044858455658,-0.286528140306473
,3720446291.14241,50.5496864318848,,,-0.271468132734299,-0.2808877825737
,3720446291.16241,50.6996879577637,,,-0.267729997634888,-0.275343090295792
,3720446291.18241,50.8496856689453,,,-0.263852596282959,-0.269899249076843
,3720446291.20241,50.9996871948242,,,-0.259856551885605,-0.264560163021088
,3720446291.22241,51.1496849060059,,,-0.255761384963989,-0.259329229593277
,3720446291.24241,51.2996864318848,,,-0.251585483551025,-0.254209160804749
,3720446291.26241,51.4496879577637,,,-0.247345924377441,-0.249201938509941
,3720446291.28241,51.5996856689453,,,-0.243058860301971,-0.24430938065052
,3720446291.30241,51.7496871948242,,,-0.238739028573036,-0.239532440900803
,3720446291.32241,51.8996849060059,,,-0.234400123357773,-0.234871700406075
,3720446291.34241,52.0496864318848,,,-0.230054721236229,-0.230327397584915
,3720446291.36241,52.1996879577637,,,-0.225714221596718,-0.225899234414101
,3720446291.38241,52.3496856689453,,,-0.221389353275299,-0.221586957573891
,3720446291.40241,52.4996871948242,,,-0.217089533805847,-0.217389687895775
,3720446291.42241,52.6496887207031,,,-0.212823316454887,-0.213306367397308
,3720446291.44241,52.7996864318848,,,-0.208598434925079,-0.209335759282112
,3720446291.46241,52.9496879577637,,,-0.204421609640121,-0.205476298928261
,3720446291.48241,53.0996856689453,,,-0.200299173593521,-0.20172655582428
,3720446291.50241,53.2496871948242,,,-0.196236312389374,-0.198084637522697
,3720446291.52241,53.3996887207031,,,-0.192237704992294,-0.194548666477203
,3720446291.54241,53.5496864318848,,,-0.188307359814644,-0.191116616129875